Workbook

Sheet 동,층별물량표
A3: 층 | B3: 107동 (4호조합/55/46타입/58세대/15층)
B4: 갱폼 | C4: 알폼 | D4: 형틀 | E4: 해체/정리 | F4: 철근 | G4: 콘크리트
B5: M2 | C5: M2 | D5: M2 | E5: M2 | F5: TON | G5: M3
A6: 버림 | D6: 40 | G6: =85.63+142.437 -> 228.067
A7: 기초 | D7: =260+56.18+58.289 -> 374.469 | E7: =D7 -> 374.469 | F7: =47.07+63.554 -> 110.624 | G7: 1643.33
A8: B2 | D8: =2997.597+1856.972 -> 4854.569 | E8: =D8 -> 4854.569 | F8: =52.45+65.564 -> 118.014 | G8: =309.62+472.732 -> 782.352
A9: B1 | D9: =3419.37+1652.227 -> 5071.597 | E9: =D9 -> 5071.597 | F9: =74.71+77.545 -> 152.255 | G9: =563.5+683.818 -> 1247.318
A10: 1층 | B10: 651 | C10: 796 | D10: 215.69 | E10: =D10 -> 215.69 | F10: 28.57 | G10: 209.36
A11: 2층 | B11: 654 | C11: 800 | D11: 326.61 | E11: =D11 -> 326.61 | F11: 26.41 | G11: 236.35
A12: 3층 | B12: 780 | C12: 954 | F12: 21.38 | G12: 224.32 | K12: =(C12+B12) -> 1734
A13: 4층 | B13: 779 | C13: 952 | F13: 18.83 | G13: 224.29
A14: 5층 | B14: 779 | C14: 952 | F14: 18.13 | G14: 224.37
A15: 6층 | B15: 779 | C15: 952 | F15: 18.04 | G15: 224.38
A16: 7층 | B16: 779 | C16: 952 | F16: 16.78 | G16: 224.53
A17: 8층 | B17: 779 | C17: 952 | F17: 16.68 | G17: 224.55
A18: 9층 | B18: 779 | C18: 952 | F18: 16.51 | G18: 224.57
A19: 10층 | B19: 779 | C19: 952 | F19: 16.44 | G19: 224.58
A20: 11층 | B20: 779 | C20: 952 | F20: 16.39 | G20: 224.58
A21: 12층 | B21: 779 | C21: 952 | F21: 16.37 | G21: 224.58
A22: 13층 | B22: 779 | C22: 952 | F22: 16.38 | G22: 224.58
A23: 14층 | B23: 812 | C23: 992 | F23: 16.31 | G23: 224.59
A24: 15층 | B24: 762 | C24: 931 | F24: 16.52 | G24: 195.56
A25: PH1층 | D25: 354.474 | E25: =D25 -> 354.474 | F25: 9.93 | G25: 101.54
A26: PH2층 | D26: 337.262 | E26: =D26 -> 337.262 | F26: 2.52 | G26: 40.25
B49: =SUM(B6:B48) -> 11449 | C49: =SUM(C6:C48) -> 13993 | D49: =SUM(D6:D48) -> 11574.671 | E49: =SUM(E6:E48) -> 11534.671 | F49: =SUM(F7:F26) -> 673.083 | G49: =SUM(G6:G48) -> 7378.047

Sheet 골조표준공정 일수고정 산식표
A3: 구분 | B3: 셀렉트박스명 | C3: 세부공종 | D3: 단위 | E3: 수량 | F3: 인당 1일 작업량 | G3: 총작업인원 | H3: 1일 투입인원 | I3: 산정 기준 | J3: 투입장비명 | K3: 장비대수 | L3: 직영 순작업일 | M3: 간접일 | N3: 총작업일수 | O3: 간접작업항목
A4: 버림 | B4: 표준공정 | C4: 1.버림틀설치 | D4: ㎡ | E4: ='동,층별물량표'!D6 -> 40 | F4: 10 | G4: =E4/F4 -> 4 | H4: =ROUNDUP(G4/L4,0) -> 4 | I4: 일수고정 | L4: 1 | N4: =ROUNDUP(L4+M4, 0) -> 1
C5: 2.버림타설 | D5: ㎥ | E5: ='동,층별물량표'!G6 -> 228.067 | F5: 130 | G5: =H5*L5 -> 5 | H5: =K5*5 -> 5 | I5: 장비대수*4명 /버림부분 | J5: 콘크리트 펌프차 | K5: =CEILING(MIN(2, E5/I11), 1) -> 1 | L5: =MAX(1, IF(E5/(F5*H5) - INT(E5/(F5*H5)) < 0.5, ROUNDDOWN(E5/(F5*H5),0), ROUNDUP(E5/(F5*H5),0) ) ) -> 1 | M5: 1 | N5: =ROUNDUP(L5+M5, 0) -> 2 | O5: 양생
A6: 기초 | B6: 표준공정 | C6: 3.먹메김 | H6: 3 | I6: 일수고정 | L6: 1 | N6: =ROUNDUP(L6+M6, 0) -> 1
C7: 4.기초철근조립 | D7: ton | E7: ='동,층별물량표'!F7 -> 110.624 | F7: 1.1 | G7: =ROUNDUP(E7/F7,0) -> 101 | H7: =ROUNDUP(G7/L7,0) -> 17 | I7: 일수고정 | L7: 6 | M7: 0.5 | N7: =ROUNDUP(L7+M7, 0) -> 7 | O7: 검측
C8: 5.끊어치기 작업 | D8: ㎡ | E8: ='동,층별물량표'!D7 -> 374.469 | F8: 10 | G8: =ROUNDUP(E8/F8,0) -> 38 | H8: =ROUNDUP(G8/L8,0) -> 19 | I8: 일수고정 | L8: 2 | M8: 0.5 | N8: =ROUNDUP(L8+M8, 0) -> 3 | O8: 검측
C9: 6.기초타설 | D9: ㎥ | E9: ='동,층별물량표'!G7 -> 1643.33 | F9: 130 | G9: =H9*L9 -> 10 | H9: =K9*5 -> 10 | I9: 장비대수*5명 /기초부분 | J9: 콘크리트 펌프차 | K9: =CEILING(MIN(2, E9/I10), 1) -> 2 | L9: =MAX(1, IF(E9/(F9*H9) - INT(E9/(F9*H9)) < 0.5, ROUNDDOWN(E9/(F9*H9),0), ROUNDUP(E9/(F9*H9),0) ) ) -> 1 | M9: 3 | N9: =ROUNDUP(L9+M9, 0) -> 4 | O9: 양생
H10: 기초 대당타설량 | I10: 650 | K10: 펌프차 대수산정기준 : 4호조합 동별 최대 2대
H11: 버림 | I11: 650
A12: 지하2층 | B12: 표준공정 | C12: 1.먹매김(1일) | H12: 3 | I12: 일수고정 | L12: 1 | N12: =ROUNDUP(L12+M12, 0) -> 1
C13: 2.옹벽철근조립 | D13: ton | E13: ='동,층별물량표'!F8*0.45 -> 53.1063 | F13: 0.8 | G13: =ROUNDUP(E13/F13,0) -> 67 | H13: =ROUNDUP(G13/L13,0) -> 14 | I13: 일수고정 | L13: 5 | M13: 0.5 | N13: =ROUNDUP(L13+M13, 0) -> 6 | O13: 검측
C14: 3.지하2층거푸집설치 | D14: ㎡ | E14: ='동,층별물량표'!D8*0.95 -> 4611.8405 | F14: 11 | G14: =ROUNDUP(E14/F14,0) -> 420 | H14: =ROUNDUP(G14/L14,0) -> 25 | I14: 일수고정 | L14: 17 | M14: 1 | N14: =ROUNDUP(L14+M14, 0) -> 18 | O14: 보강/검측
C15: 4.보슬라브철근조립 | D15: ton | E15: ='동,층별물량표'!F8*0.55 -> 64.9077 | F15: 0.8 | G15: =ROUNDUP(E15/F15,0) -> 82 | H15: =ROUNDUP(G15/L15,0) -> 17 | I15: 일수고정 | L15: 5 | M15: 0.5 | N15: =ROUNDUP(L15+M15, 0) -> 6 | O15: 검측
C16: 5.마감작업 | E16: ='동,층별물량표'!D8*0.05 -> 242.72845 | F16: 11 | G16: =ROUNDUP(E16/F16,0) -> 23 | H16: =ROUNDUP(G16/L16,0) -> 12 | I16: 일수고정 | L16: 2 | M16: 0.5 | N16: =ROUNDUP(L16+M16, 0) -> 3 | O16: 검측
C17: 6.타설 | D17: ㎥ | E17: ='동,층별물량표'!G8 -> 782.352 | F17: 130 | G17: =H17*L17 -> 10 | H17: =K17*5 -> 10 | I17: 장비대수*5명 /지하골조부분 | J17: 콘크리트 펌프차 | K17: =CEILING(MIN(2, E17/I28), 1) -> 2 | L17: =MAX(1, IF(E17/(F17*H17) - INT(E17/(F17*H17)) < 0.5, ROUNDDOWN(E17/(F17*H17),0), ROUNDUP(E17/(F17*H17),0) ) ) -> 1 | M17: 3 | N17: =ROUNDUP(L17+M17, 0) -> 4 | O17: 양생
C18: *거푸집해체정리 | E18: =E14+E16 -> 4854.569 | F18: 50 | G18: =ROUNDUP(E18/F18,0) -> 98 | H18: =ROUNDUP(G18/L18,0) -> 7 | I18: 일수고정 | L18: 16 | N18: =ROUNDUP(L18+M18, 0) -> 16
A19: 지하1층 | B19: 표준공정 | C19: 7.먹매김(1일) | H19: 3 | I19: 일수고정 | M19: 1 | N19: =ROUNDUP(L19+M19, 0) -> 1
C20: 8.벽 철근조립 | D20: ton | E20: ='동,층별물량표'!F9*0.45 -> 68.51475 | F20: 0.7 | G20: =ROUNDUP(E20/F20,0) -> 98 | H20: =ROUNDUP(G20/L20,0) -> 20 | I20: 일수고정 | L20: 5 | M20: 0.5 | N20: =ROUNDUP(L20+M20, 0) -> 6 | O20: 검측
C21: 9.지하1층 거푸집 설치 | D21: ㎡ | E21: ='동,층별물량표'!D9*0.9 -> 4564.4373 | F21: 9 | G21: =ROUNDUP(E21/F21,0) -> 508 | H21: =ROUNDUP(G21/L21,0) -> 27 | I21: 일수고정 | L21: 19 | M21: 0.5 | N21: =ROUNDUP(L21+M21, 0) -> 20 | O21: 검측
C22: 10.보슬라브 철근조립 | D22: ton | E22: ='동,층별물량표'!F9*0.55 -> 83.74025 | F22: 0.7 | G22: =ROUNDUP(E22/F22,0) -> 120 | H22: =ROUNDUP(G22/L22,0) -> 24 | I22: 일수고정 | L22: 5 | M22: 0.5 | N22: =ROUNDUP(L22+M22, 0) -> 6 | O22: 검측
C23: 11.1차 마감작업 | D23: ㎡ | E23: ='동,층별물량표'!D9*0.05 -> 253.57985 | F23: 10 | G23: =ROUNDUP(E23/F23,0) -> 26 | H23: =ROUNDUP(G23/L23,0) -> 13 | I23: 일수고정 | L23: 2 | M23: 0.5 | N23: =ROUNDUP(L23+M23, 0) -> 3 | O23: 검측
C24: 12.1차 타설 | D24: ㎥ | E24: ='동,층별물량표'!G9*0.6 -> 748.3908 | F24: 130 | G24: =H24*L24 -> 10 | H24: =K24*5 -> 10 | I24: 장비대수*5명 /지하골조부분 | J24: 콘크리트 펌프차 | K24: =CEILING(MIN(2, E24/I28), 1) -> 2 | L24: =MAX(1, IF(E24/(F24*H24) - INT(E24/(F24*H24)) < 0.5, ROUNDDOWN(E24/(F24*H24),0), ROUNDUP(E24/(F24*H24),0) ) ) -> 1 | M24: 3 | N24: =ROUNDUP(L24+M24, 0) -> 4 | O24: 양생
C25: 12.2차 마감작업 | D25: ㎡ | E25: ='동,층별물량표'!D9*0.05 -> 253.57985 | F25: 10 | G25: =ROUNDUP(E25/F25,0) -> 26 | H25: =ROUNDUP(G25/L25,0) -> 13 | I25: 일수고정 | L25: 2 | M25: 0.5 | N25: =ROUNDUP(L25+M25, 0) -> 3 | O25: 검측
C26: 13.2차 타설 | D26: ㎥ | E26: ='동,층별물량표'!G9*0.4 -> 498.9272 | F26: 130 | G26: =H26*L26 -> 5 | H26: =K26*5 -> 5 | I26: 장비대수*5명 /지하골조부분 | J26: 콘크리트 펌프차 | K26: =CEILING(MIN(2, E26/I28), 1) -> 1 | L26: =MAX(1, IF(E26/(F26*H26) - INT(E26/(F26*H26)) < 0.5, ROUNDDOWN(E26/(F26*H26),0), ROUNDUP(E26/(F26*H26),0) ) ) -> 1 | M26: 3 | N26: =ROUNDUP(L26+M26, 0) -> 4 | O26: 양생
C27: *거푸집해체정리 | D27: ㎡ | E27: =E21+E23+E25 -> 5071.597 | F27: 50 | G27: =ROUNDUP(E27/F27,0) -> 102 | H27: =ROUNDUP(G27/L27,0) -> 5 | I27: 일수고정 | L27: 22 | N27: =ROUNDUP(L27+M27, 0) -> 22
H28: 지하 대당타설량 | I28: 500
A30: 셋팅층 | B30: 표준공정 | C30: 1.먹매김(1일) | H30: 3 | M30: 1 | N30: =ROUNDUP(L30+M30, 0) -> 1 | O30: 검측
C31: 2.갱폼설치 | D31: ㎡ | E31: ='동,층별물량표'!B10 -> 651 | F31: 30 | G31: =ROUNDUP(E31/F31,0) -> 22 | H31: =ROUNDUP(G31/L31,0) -> 11 | I31: 일수고정 | L31: 2 | M31: 6 | N31: =ROUNDUP(L31+M31, 0) -> 8 | O31: 앵커/안전발판
C32: 3.옹벽철근 조립 | D32: ton | E32: ='동,층별물량표'!F10*0.5 -> 14.285 | F32: 0.8 | G32: =ROUNDUP(E32/F32,0) -> 18 | H32: =ROUNDUP(G32/L32,0) -> 9 | I32: 일수고정 | L32: 2 | M32: 0.5 | N32: 2 | O32: 검측
C33: 4.알폼조립 | D33: ㎡ | E33: ='동,층별물량표'!C10 -> 796 | F33: 30 | G33: =ROUNDUP(E33/F33,0) -> 27 | H33: =ROUNDUP(G33/L33,0) -> 7 | I33: 일수고정 | L33: 4 | M33: 0.5 | N33: 4 | O33: 검측
C34: 5.슬라브철근 조립 | D34: ton | E34: ='동,층별물량표'!F10*0.5 -> 14.285 | F34: 0.9 | G34: =ROUNDUP(E34/F34,0) -> 16 | H34: =ROUNDUP(G34/L34,0) -> 8 | I34: 일수고정 | L34: 2 | M34: 0.5 | N34: 2 | O34: 검측
C35: 6.타설 | D35: ㎥ | E35: ='동,층별물량표'!G10 -> 209.36 | F35: 130 | G35: =H35*L35 -> 5 | H35: =K35*5 -> 5 | I35: 장비대수*6명 /셋팅층 | J35: 콘크리트 펌프차 | K35: =CEILING(MIN(2, E35/I36), 1) -> 1 | L35: =MAX(1, IF(E35/(F35*H35) - INT(E35/(F35*H35)) < 0.5, ROUNDDOWN(E35/(F35*H35),0), ROUNDUP(E35/(F35*H35),0) ) ) -> 1 | M35: 2 | N35: =ROUNDUP(L35+M35, 0) -> 3 | O35: 양생
H36: 1층 대당타설량 | I36: 400
A38: 기준층 | B38: 8일 사이클 | C38: 1.먹매김(1일) | H38: 3 | M38: 1 | N38: =ROUNDUP(L38+M38, 0) -> 1 | O38: 검측
C39: 2.갱폼설치 | D39: ㎡ | E39: ='동,층별물량표'!B13 -> 779 | F39: 60 | G39: =ROUNDUP(E39/F39,0) -> 13 | H39: =ROUNDUP(G39/L39,0) -> 13 | I39: 일수고정 | L39: 1 | M39: 1 | N39: =ROUNDUP(L39+M39, 0) -> 2 | O39: 보강/검측
C40: 3.옹벽철근 조립 | D40: ton | E40: =18.83*0.5 -> 9.415 | F40: 0.8 | G40: =ROUNDUP(E40/F40,0) -> 12 | H40: =ROUNDUP(G40/L40,0) -> 12 | I40: 일수고정 | L40: 1 | M40: 0.5 | N40: =ROUNDUP(L40+M40, 0) -> 2 | O40: 검측
C41: 4.알폼조립 | D41: ㎡ | E41: =1731*0.55 -> 952.05 | F41: 60 | G41: =ROUNDUP(E41/F41,0) -> 16 | H41: =ROUNDUP(G41/L41,0) -> 16 | I41: 일수고정 | L41: 1 | M41: 0.5 | N41: =ROUNDUP(L41+M41, 0) -> 2 | O41: 검측
C42: 5.슬라브철근 조립 | D42: ton | E42: =18.83*0.5 -> 9.415 | F42: 0.9 | G42: =ROUNDUP(E42/F42,0) -> 11 | H42: =ROUNDUP(G42/L42,0) -> 11 | I42: 일수고정 | L42: 1 | M42: 0.5 | N42: =ROUNDUP(L42+M42, 0) -> 2 | O42: 검측
C43: 6.타설 | D43: ㎥ | E43: ='동,층별물량표'!G13 -> 224.29 | F43: 130 | G43: =H43*L43 -> 5 | H43: =K43*5 -> 5 | I43: 장비대수*6명 /일반층 | J43: 콘크리트 펌프차 | K43: =CEILING(MIN(2, E43/I44), 1) -> 1 | L43: =MAX(1, IF(E43/(F43*H43) - INT(E43/(F43*H43)) < 0.5, ROUNDDOWN(E43/(F43*H43),0), ROUNDUP(E43/(F43*H43),0) ) ) -> 1 | M43: 2 | N43: =ROUNDUP(L43+M43, 0) -> 3 | O43: 양생
H44: 일반층 대당타설량 | I44: 320
...

Sheet 골조표준공정 일수고정 산식표 (2)
A3: 구분 | B3: 셀렉트박스명 | C3: 세부공종 | D3: 단위 | E3: 수량 | F3: 인당 생산성 | G3: 총투입인원 | H3: 1일 투입인원 | I3: 산정 기준 | J3: 장비대수 | K3: 순작업일 | L3: 간접일 | M3: 총작업일수 | N3: 간접작업항목
A4: 버림 | B4: 표준공정 | C4: 1.버림틀설치 | D4: ㎡ | E4: ='동,층별물량표'!D6 -> 40 | F4: 10 | G4: =E4/F4 -> 4 | H4: =ROUNDUP(G4/K4,0) -> 4 | I4: 일수고정 | K4: 1 | M4: =ROUNDUP(K4+L4, 0) -> 1
C5: 2.버림타설 | D5: ㎥ | E5: ='동,층별물량표'!G6 -> 228.067 | F5: 130 | G5: =H5*K5 -> 5 | H5: =J5*5 -> 5 | I5: 장비대수*4명 /버림부분 | J5: =CEILING(MIN(2, E5/I11), 1) -> 1 | K5: =MAX(1, IF(E5/(F5*H5) - INT(E5/(F5*H5)) < 0.5, ROUNDDOWN(E5/(F5*H5),0), ROUNDUP(E5/(F5*H5),0) ) ) -> 1 | L5: 1 | M5: =ROUNDUP(K5+L5, 0) -> 2 | N5: 양생
A6: 기초 | B6: 표준공정 | C6: 3.먹메김 | H6: 3 | I6: 일수고정 | K6: 1 | M6: =ROUNDUP(K6+L6, 0) -> 1
C7: 4.기초철근조립 | D7: ton | E7: ='동,층별물량표'!F7 -> 110.624 | F7: 1.1 | G7: =ROUNDUP(E7/F7,0) -> 101 | H7: =ROUNDUP(G7/K7,0) -> 17 | I7: 일수고정 | K7: 6 | L7: 0.5 | M7: =ROUNDUP(K7+L7, 0) -> 7 | N7: 검측
C8: 5.끊어치기 작업 | D8: ㎡ | E8: ='동,층별물량표'!D7 -> 374.469 | F8: 10 | G8: =ROUNDUP(E8/F8,0) -> 38 | H8: =ROUNDUP(G8/K8,0) -> 19 | I8: 일수고정 | K8: 2 | L8: 0.5 | M8: =ROUNDUP(K8+L8, 0) -> 3 | N8: 검측
C9: 6.기초타설 | D9: ㎥ | E9: ='동,층별물량표'!G7 -> 1643.33 | F9: 130 | G9: =H9*K9 -> 10 | H9: =J9*5 -> 10 | I9: 장비대수*5명 /기초부분 | J9: =CEILING(MIN(2, E9/I10), 1) -> 2 | K9: =MAX(1, IF(E9/(F9*H9) - INT(E9/(F9*H9)) < 0.5, ROUNDDOWN(E9/(F9*H9),0), ROUNDUP(E9/(F9*H9),0) ) ) -> 1 | L9: 3 | M9: =ROUNDUP(K9+L9, 0) -> 4 | N9: 양생 | P9: 버림 대당타설량 | Q9: 650
H10: 기초 대당타설량 | I10: 650 | J10: 펌프차 대수산정기준 : 4호조합 동별 최대 2대 | P10: 기초 대당타설량 | Q10: 650
H11: 버림 | I11: 650 | P11: 지하 대당타설량 | Q11: 500
A12: 지하2층 | B12: 표준공정 | C12: 1.먹매김(1일) | H12: 3 | I12: 일수고정 | K12: 1 | M12: =ROUNDUP(K12+L12, 0) -> 1 | P12: 일반층 대당타설량 | Q12: 400
C13: 2.옹벽철근조립 | D13: ton | E13: ='동,층별물량표'!F8*0.45 -> 53.1063 | F13: 0.8 | G13: =ROUNDUP(E13/F13,0) -> 67 | H13: =ROUNDUP(G13/K13,0) -> 14 | I13: 일수고정 | K13: 5 | L13: 0.5 | M13: =ROUNDUP(K13+L13, 0) -> 6 | N13: 검측 | P13: 셋팅층 대당타설량 | Q13: 400
C14: 3.지하2층거푸집설치 | D14: ㎡ | E14: ='동,층별물량표'!D8*0.95 -> 4611.8405 | F14: 11 | G14: =ROUNDUP(E14/F14,0) -> 420 | H14: =ROUNDUP(G14/K14,0) -> 25 | I14: 일수고정 | K14: 17 | L14: 1 | M14: =ROUNDUP(K14+L14, 0) -> 18 | N14: 보강/검측 | P14: 기준층 대당타설량 | Q14: 320
C15: 4.보슬라브철근조립 | D15: ton | E15: ='동,층별물량표'!F8*0.55 -> 64.9077 | F15: 0.8 | G15: =ROUNDUP(E15/F15,0) -> 82 | H15: =ROUNDUP(G15/K15,0) -> 17 | I15: 일수고정 | K15: 5 | L15: 0.5 | M15: =ROUNDUP(K15+L15, 0) -> 6 | N15: 검측 | P15: PH층 대당타설량 | Q15: 230
C16: 5.마감작업 | E16: ='동,층별물량표'!D8*0.05 -> 242.72845 | F16: 11 | G16: =ROUNDUP(E16/F16,0) -> 23 | H16: =ROUNDUP(G16/K16,0) -> 12 | I16: 일수고정 | K16: 2 | L16: 0.5 | M16: =ROUNDUP(K16+L16, 0) -> 3 | N16: 검측
C17: 6.타설 | D17: ㎥ | E17: ='동,층별물량표'!G8 -> 782.352 | F17: 130 | G17: =H17*K17 -> 10 | H17: =J17*5 -> 10 | I17: 장비대수*5명 /지하골조부분 | J17: =CEILING(MIN(2, E17/I28), 1) -> 2 | K17: =MAX(1, IF(E17/(F17*H17) - INT(E17/(F17*H17)) < 0.5, ROUNDDOWN(E17/(F17*H17),0), ROUNDUP(E17/(F17*H17),0) ) ) -> 1 | L17: 3 | M17: =ROUNDUP(K17+L17, 0) -> 4 | N17: 양생
C18: *거푸집해체정리 | E18: =E14+E16 -> 4854.569 | F18: 50 | G18: =ROUNDUP(E18/F18,0) -> 98 | H18: =ROUNDUP(G18/K18,0) -> 7 | I18: 일수고정 | K18: 16 | M18: =ROUNDUP(K18+L18, 0) -> 16
A19: 지하1층 | B19: 표준공정 | C19: 7.먹매김(1일) | H19: 3 | I19: 일수고정 | L19: 1 | M19: =ROUNDUP(K19+L19, 0) -> 1
C20: 8.벽 철근조립 | D20: ton | E20: ='동,층별물량표'!F9*0.45 -> 68.51475 | F20: 0.7 | G20: =ROUNDUP(E20/F20,0) -> 98 | H20: =ROUNDUP(G20/K20,0) -> 20 | I20: 일수고정 | K20: 5 | L20: 0.5 | M20: =ROUNDUP(K20+L20, 0) -> 6 | N20: 검측
C21: 9.지하1층 거푸집 설치 | D21: ㎡ | E21: ='동,층별물량표'!D9*0.9 -> 4564.4373 | F21: 9 | G21: =ROUNDUP(E21/F21,0) -> 508 | H21: =ROUNDUP(G21/K21,0) -> 27 | I21: 일수고정 | K21: 19 | L21: 0.5 | M21: =ROUNDUP(K21+L21, 0) -> 20 | N21: 검측
C22: 10.보슬라브 철근조립 | D22: ton | E22: ='동,층별물량표'!F9*0.55 -> 83.74025 | F22: 0.7 | G22: =ROUNDUP(E22/F22,0) -> 120 | H22: =ROUNDUP(G22/K22,0) -> 24 | I22: 일수고정 | K22: 5 | L22: 0.5 | M22: =ROUNDUP(K22+L22, 0) -> 6 | N22: 검측
C23: 11.1차 마감작업 | D23: ㎡ | E23: ='동,층별물량표'!D9*0.05 -> 253.57985 | F23: 10 | G23: =ROUNDUP(E23/F23,0) -> 26 | H23: =ROUNDUP(G23/K23,0) -> 13 | I23: 일수고정 | K23: 2 | L23: 0.5 | M23: =ROUNDUP(K23+L23, 0) -> 3 | N23: 검측
C24: 12.1차 타설 | D24: ㎥ | E24: ='동,층별물량표'!G9*0.6 -> 748.3908 | F24: 130 | G24: =H24*K24 -> 10 | H24: =J24*5 -> 10 | I24: 장비대수*5명 /지하골조부분 | J24: =CEILING(MIN(2, E24/I28), 1) -> 2 | K24: =MAX(1, IF(E24/(F24*H24) - INT(E24/(F24*H24)) < 0.5, ROUNDDOWN(E24/(F24*H24),0), ROUNDUP(E24/(F24*H24),0) ) ) -> 1 | L24: 3 | M24: =ROUNDUP(K24+L24, 0) -> 4 | N24: 양생
C25: 12.2차 마감작업 | D25: ㎡ | E25: ='동,층별물량표'!D9*0.05 -> 253.57985 | F25: 10 | G25: =ROUNDUP(E25/F25,0) -> 26 | H25: =ROUNDUP(G25/K25,0) -> 13 | I25: 일수고정 | K25: 2 | L25: 0.5 | M25: =ROUNDUP(K25+L25, 0) -> 3 | N25: 검측
C26: 13.2차 타설 | D26: ㎥ | E26: ='동,층별물량표'!G9*0.4 -> 498.9272 | F26: 130 | G26: =H26*K26 -> 5 | H26: =J26*5 -> 5 | I26: 장비대수*5명 /지하골조부분 | J26: =CEILING(MIN(2, E26/I28), 1) -> 1 | K26: =MAX(1, IF(E26/(F26*H26) - INT(E26/(F26*H26)) < 0.5, ROUNDDOWN(E26/(F26*H26),0), ROUNDUP(E26/(F26*H26),0) ) ) -> 1 | L26: 3 | M26: =ROUNDUP(K26+L26, 0) -> 4 | N26: 양생
C27: *거푸집해체정리 | D27: ㎡ | E27: =E21+E23+E25 -> 5071.597 | F27: 50 | G27: =ROUNDUP(E27/F27,0) -> 102 | H27: =ROUNDUP(G27/K27,0) -> 5 | I27: 일수고정 | K27: 22 | M27: =ROUNDUP(K27+L27, 0) -> 22
H28: 지하 대당타설량 | I28: 500
A30: 셋팅층 | B30: 표준공정 | C30: 1.먹매김(1일) | H30: 3 | L30: 1 | M30: =ROUNDUP(K30+L30, 0) -> 1 | N30: 검측
C31: 2.갱폼설치 | D31: ㎡ | E31: ='동,층별물량표'!B10 -> 651 | F31: 30 | G31: =ROUNDUP(E31/F31,0) -> 22 | H31: =ROUNDUP(G31/K31,0) -> 11 | I31: 일수고정 | K31: 2 | L31: 6 | M31: =ROUNDUP(K31+L31, 0) -> 8 | N31: 앵커/안전발판
C32: 3.옹벽철근 조립 | D32: ton | E32: ='동,층별물량표'!F10*0.5 -> 14.285 | F32: 0.8 | G32: =ROUNDUP(E32/F32,0) -> 18 | H32: =ROUNDUP(G32/K32,0) -> 9 | I32: 일수고정 | K32: 2 | L32: 0.5 | M32: 2 | N32: 검측
C33: 4.알폼조립 | D33: ㎡ | E33: ='동,층별물량표'!C10 -> 796 | F33: 30 | G33: =ROUNDUP(E33/F33,0) -> 27 | H33: =ROUNDUP(G33/K33,0) -> 7 | I33: 일수고정 | K33: 4 | L33: 0.5 | M33: 4 | N33: 검측
C34: 5.슬라브철근 조립 | D34: ton | E34: ='동,층별물량표'!F10*0.5 -> 14.285 | F34: 0.9 | G34: =ROUNDUP(E34/F34,0) -> 16 | H34: =ROUNDUP(G34/K34,0) -> 8 | I34: 일수고정 | K34: 2 | L34: 0.5 | M34: 2 | N34: 검측
C35: 6.타설 | D35: ㎥ | E35: ='동,층별물량표'!G10 -> 209.36 | F35: 130 | G35: =H35*K35 -> 5 | H35: =J35*5 -> 5 | I35: 장비대수*6명 /셋팅층 | J35: =CEILING(MIN(2, E35/I36), 1) -> 1 | K35: =MAX(1, IF(E35/(F35*H35) - INT(E35/(F35*H35)) < 0.5, ROUNDDOWN(E35/(F35*H35),0), ROUNDUP(E35/(F35*H35),0) ) ) -> 1 | L35: 2 | M35: =ROUNDUP(K35+L35, 0) -> 3 | N35: 양생
H36: 1층 대당타설량 | I36: 400
A38: 기준층 | B38: 8일 사이클 | C38: 1.먹매김(1일) | H38: 3 | L38: 1 | M38: =ROUNDUP(K38+L38, 0) -> 1 | N38: 검측
C39: 2.갱폼설치 | D39: ㎡ | E39: ='동,층별물량표'!B13 -> 779 | F39: 60 | G39: =ROUNDUP(E39/F39,0) -> 13 | H39: =ROUNDUP(G39/K39,0) -> 13 | I39: 일수고정 | K39: 1 | L39: 1 | M39: =ROUNDUP(K39+L39, 0) -> 2 | N39: 보강/검측
C40: 3.옹벽철근 조립 | D40: ton | E40: =18.83*0.5 -> 9.415 | F40: 0.8 | G40: =ROUNDUP(E40/F40,0) -> 12 | H40: =ROUNDUP(G40/K40,0) -> 12 | I40: 일수고정 | K40: 1 | L40: 0.5 | M40: =ROUNDUP(K40+L40, 0) -> 2 | N40: 검측
C41: 4.알폼조립 | D41: ㎡ | E41: =1731*0.55 -> 952.05 | F41: 60 | G41: =ROUNDUP(E41/F41,0) -> 16 | H41: =ROUNDUP(G41/K41,0) -> 16 | I41: 일수고정 | K41: 1 | L41: 0.5 | M41: =ROUNDUP(K41+L41, 0) -> 2 | N41: 검측
C42: 5.슬라브철근 조립 | D42: ton | E42: =18.83*0.5 -> 9.415 | F42: 0.9 | G42: =ROUNDUP(E42/F42,0) -> 11 | H42: =ROUNDUP(G42/K42,0) -> 11 | I42: 일수고정 | K42: 1 | L42: 0.5 | M42: =ROUNDUP(K42+L42, 0) -> 2 | N42: 검측
C43: 6.타설 | D43: ㎥ | E43: ='동,층별물량표'!G13 -> 224.29 | F43: 130 | G43: =H43*K43 -> 5 | H43: =J43*5 -> 5 | I43: 장비대수*6명 /일반층 | J43: =CEILING(MIN(2, E43/I44), 1) -> 1 | K43: =MAX(1, IF(E43/(F43*H43) - INT(E43/(F43*H43)) < 0.5, ROUNDDOWN(E43/(F43*H43),0), ROUNDUP(E43/(F43*H43),0) ) ) -> 1 | L43: 2 | M43: =ROUNDUP(K43+L43, 0) -> 3 | N43: 양생
H44: 일반층 대당타설량 | I44: 320
...
