Workbook

Sheet 지상층
A1: 구분 | B1: 층수 | C1: 세부공종 | D1: 단위 | E1: 수량 | F1: 인당 생산성 | G1: 총 투입인원 | H1: 1일 투입인원 | I1: 산정 기준 | J1: 작업조 기준인원 | K1: 기준 인원 | L1: 최대 작업조 | M1: 부분별 보정계수 | N1: 최대투입인원 | O1: 투입장비명 | P1: 장비대수 | Q1: 순작업일 | R1: 간접일 | S1: 총작업일수 | T1: 간접작업항목
A2: 버림 | C2: 버림틀설치 | D2: ㎡ | E2: 40 | F2: 10 | G2: {=E2/F2} -> 4 | H2: {=ROUNDUP(G2/Q2,0)} -> 4 | I2: 일수고정 | J2: 2 | K2: 6 | L2: {=N2/J2} -> 3 | M2: {=1} -> 1 | N2: {=ROUND(M2*K2/J2,0)*J2} -> 6 | Q2: 1 | S2: {=ROUNDUP(Q2+R2,0)} -> 1
C3: 버림타설 | D3: ㎥ | E3: 228 | F3: 130 | G3: {=H3*Q3} -> 5 | H3: {=P3*5} -> 5 | I3: 장비대수*4명 /버림부분 | M3: 1 | O3: 콘크리트 펌프차 | P3: {=CEILING(MIN(2,E3/'타설 '!B2),1)} -> 1 | Q3: {=MAX(1,IF(E3/(F3*H3)-INT(E3/(F3*H3))<0.5,ROUNDDOWN(E3/(F3*H3),0),ROUNDUP(E3/(F3*H3),0)))} -> 1 | R3: 1 | S3: {=ROUNDUP(Q3+R3,0)} -> 2 | T3: 양생
A4: 기초 | C4: 먹매김 | D4: ㎡ | H4: 3 | I4: 일수고정 | J4: 3 | K4: 6 | L4: {=N4/J4} -> 2 | M4: 1 | N4: {=ROUND(M4*K4/J4,0)*J4} -> 6 | Q4: 1 | S4: {=ROUNDUP(Q4+R4,0)} -> 1
C5: 기초철근조립 | D5: ton | E5: 110.62 | F5: 1.1 | G5: {=ROUNDUP(E5/F5,0)} -> 101 | H5: {=ROUNDUP(G5/Q5,0)} -> 17 | I5: 일수고정 | J5: 4 | K5: 24 | L5: {=N5/J5} -> 8 | M5: 1.3 | N5: {=ROUND(M5*K5/J5,0)*J5} -> 32 | Q5: 6 | R5: 0.5 | S5: {=ROUNDUP(Q5+R5,0)} -> 7 | T5: 검측
C6: 끊어치기 작업 | D6: ㎡ | E6: 120 | F6: 10 | G6: {=ROUNDUP(E6/F6,0)} -> 12 | H6: {=ROUNDUP(G6/Q6,0)} -> 6 | I6: 일수고정 | J6: 3 | K6: 6 | L6: {=N6/J6} -> 2 | M6: 1 | N6: {=ROUND(M6*K6/J6,0)*J6} -> 6 | Q6: 2 | R6: 0.5 | S6: {=ROUNDUP(Q6+R6,0)} -> 3 | T6: 검측
C7: 기초타설 | D7: ㎥ | E7: 1643 | F7: 130 | G7: {=H7*Q7} -> 10 | H7: {=P7*5} -> 10 | I7: 장비대수*5명 /기초부분 | M7: 1 | O7: 콘크리트 펌프차 | P7: {=CEILING(MIN(2,E7/'타설 '!B3),1)} -> 2 | Q7: {=MAX(1,IF(E7/(F7*H7)-INT(E7/(F7*H7))<0.5,ROUNDDOWN(E7/(F7*H7),0),ROUNDUP(E7/(F7*H7),0)))} -> 1 | R7: 3 | S7: {=ROUNDUP(Q7+R7,0)} -> 4 | T7: 양생
A9: 지하층 | B9: B2 | C9: 먹매김 | D9: ㎡ | H9: 3 | I9: 일수고정 | J9: 3 | K9: 6 | L9: {=N9/J9} -> 2 | M9: 1 | N9: {=ROUND(M9*K9/J9,0)*J9} -> 6 | Q9: 1 | S9: {=ROUNDUP(Q9+R9,0)} -> 1
C10: 벽 철근조립 | D10: ton | E10: 53.1 | F10: 0.8 | G10: {=ROUNDUP(E10/F10,0)} -> 67 | H10: {=ROUNDUP(G10/Q10,0)} -> 14 | I10: 일수고정 | J10: 3 | K10: 18 | L10: {=N10/J10} -> 7 | M10: 1.2 | N10: {=ROUND(M10*K10/J10,0)*J10} -> 21 | Q10: 5 | R10: 0.5 | S10: {=ROUNDUP(Q10+R10,0)} -> 6 | T10: 검측
C11: 지하2층 거푸집설치 | D11: ㎡ | E11: 4612.25 | F11: 11 | G11: {=ROUNDUP(E11/F11,0)} -> 420 | H11: {=ROUNDUP(G11/Q11,0)} -> 25 | I11: 일수고정 | J11: 2 | K11: 16 | L11: {=N11/J11} -> 10 | M11: 1.2 | N11: {=ROUND(M11*K11/J11,0)*J11} -> 20 | Q11: 17 | R11: 1 | S11: {=ROUNDUP(Q11+R11,0)} -> 18 | T11: 보강/검측
C12: 보슬라브 철근조립 | D12: ton | E12: 64.91 | F12: 0.8 | G12: {=ROUNDUP(E12/F12,0)} -> 82 | H12: {=ROUNDUP(G12/Q12,0)} -> 17 | I12: 일수고정 | J12: 3 | K12: 18 | L12: {=N12/J12} -> 7 | M12: 1.2 | N12: {=ROUND(M12*K12/J12,0)*J12} -> 21 | Q12: 5 | R12: 0.5 | S12: {=ROUNDUP(Q12+R12,0)} -> 6 | T12: 검측
C13: 마감작업 | D13: ㎡ | E13: 242.75 | F13: 11 | G13: {=ROUNDUP(E13/F13,0)} -> 23 | H13: {=ROUNDUP(G13/Q13,0)} -> 12 | I13: 일수고정 | J13: 2 | K13: 12 | L13: {=N13/J13} -> 7 | M13: 1.2 | N13: {=ROUND(M13*K13/J13,0)*J13} -> 14 | Q13: 2 | R13: 0.5 | S13: {=ROUNDUP(Q13+R13,0)} -> 3 | T13: 검측
C14: 타설 | D14: ㎥ | E14: 782 | F14: 130 | G14: {=H14*Q14} -> 10 | H14: {=P14*5} -> 10 | I14: 장비대수*5명 /지하골조부분 | M14: 1 | O14: 콘크리트 펌프차 | P14: {=CEILING(MIN(2,E14/'타설 '!B4),1)} -> 2 | Q14: {=MAX(1,IF(E14/(F14*H14)-INT(E14/(F14*H14))<0.5,ROUNDDOWN(E14/(F14*H14),0),ROUNDUP(E14/(F14*H14),0)))} -> 1 | R14: 3 | S14: {=ROUNDUP(Q14+R14,0)} -> 4 | T14: 양생
C15: 거푸집 해체/정리 | D15: ㎡ | E15: {=E11+E13} -> 4855 | F15: 50 | G15: {=ROUNDUP(E15/F15,0)} -> 98 | H15: {=ROUNDUP(G15/Q15,0)} -> 7 | I15: 일수고정 | J15: 2 | K15: 24 | L15: {=N15/J15} -> 14 | M15: 1.2 | N15: {=ROUND(M15*K15/J15,0)*J15} -> 28 | Q15: 16 | S15: {=ROUNDUP(Q15+R15,0)} -> 16
A16: 지하층 | B16: B1 | C16: 먹매김 | D16: ㎡ | H16: 3 | I16: 일수고정 | J16: 3 | K16: 6 | L16: {=N16/J16} -> 2 | M16: 1 | N16: {=ROUND(M16*K16/J16,0)*J16} -> 6 | R16: 1 | S16: {=ROUNDUP(Q16+R16,0)} -> 1
C17: 벽 철근조립 | D17: ton | E17: 45.68 | F17: 0.7 | G17: {=ROUNDUP(E17/F17,0)} -> 66 | H17: {=ROUNDUP(G17/Q17,0)} -> 14 | I17: 일수고정 | J17: 3 | K17: 18 | L17: {=N17/J17} -> 7 | M17: 1.2 | N17: {=ROUND(M17*K17/J17,0)*J17} -> 21 | Q17: 5 | R17: 0.5 | S17: {=ROUNDUP(Q17+R17,0)} -> 6 | T17: 검측
C18: 지하1층 거푸집 설치 | D18: ㎡ | E18: 4564.8 | F18: 9 | G18: {=ROUNDUP(E18/F18,0)} -> 508 | H18: {=ROUNDUP(G18/Q18,0)} -> 27 | I18: 일수고정 | J18: 2 | K18: 10 | L18: {=N18/J18} -> 6 | M18: 1.2 | N18: {=ROUND(M18*K18/J18,0)*J18} -> 12 | Q18: 19 | R18: 0.5 | S18: {=ROUNDUP(Q18+R18,0)} -> 20 | T18: 검측
C19: 보슬라브 철근조립 | D19: ton | E19: 45.68 | F19: 0.7 | G19: {=ROUNDUP(E19/F19,0)} -> 66 | H19: {=ROUNDUP(G19/Q19,0)} -> 14 | I19: 일수고정 | J19: 3 | K19: 18 | L19: {=N19/J19} -> 7 | M19: 1.2 | N19: {=ROUND(M19*K19/J19,0)*J19} -> 21 | Q19: 5 | R19: 0.5 | S19: {=ROUNDUP(Q19+R19,0)} -> 6 | T19: 검측
C20: 마감작업 | D20: ㎡ | E20: 253.6 | F20: 10 | G20: {=ROUNDUP(E20/F20,0)} -> 26 | H20: {=ROUNDUP(G20/Q20,0)} -> 13 | I20: 일수고정 | J20: 2 | K20: 24 | L20: {=N20/J20} -> 14 | M20: 1.2 | N20: {=ROUND(M20*K20/J20,0)*J20} -> 28 | Q20: 2 | R20: 0.5 | S20: {=ROUNDUP(Q20+R20,0)} -> 3 | T20: 검측
C21: 타설 | D21: ㎥ | E21: 748.2 | F21: 130 | G21: {=H21*Q21} -> 10 | H21: {=P21*5} -> 10 | I21: 장비대수*5명 /지하골조부분 | M21: 1 | O21: 콘크리트 펌프차 | P21: {=CEILING(MIN(2,E21/'타설 '!B4),1)} -> 2 | Q21: {=MAX(1,IF(E21/(F21*H21)-INT(E21/(F21*H21))<0.5,ROUNDDOWN(E21/(F21*H21),0),ROUNDUP(E21/(F21*H21),0)))} -> 1 | R21: 3 | S21: {=ROUNDUP(Q21+R21,0)} -> 4 | T21: 양생
C22: 벽 철근조립 | D22: ton | E22: 30.45 | F22: 0.7 | G22: {=ROUNDUP(E22/F22,0)} -> 44 | H22: {=ROUNDUP(G22/Q22,0)} -> 15 | I22: 일수고정 | J22: 3 | K22: 18 | L22: {=N22/J22} -> 7 | M22: 1.2 | N22: {=ROUND(M22*K22/J22,0)*J22} -> 21 | Q22: 3 | R22: 0.5 | S22: {=ROUNDUP(Q22+R22,0)} -> 4 | T22: 검측
C23: 피트층 거푸집 설치 | D23: ㎡ | E23: 253.6 | F23: 10 | G23: {=ROUNDUP(E23/F23,0)} -> 26 | H23: {=ROUNDUP(G23/Q23,0)} -> 13 | I23: 일수고정 | J23: 2 | K23: 24 | L23: {=N23/J23} -> 14 | M23: 1.2 | N23: {=ROUND(M23*K23/J23,0)*J23} -> 28 | Q23: 2 | R23: 0.5 | S23: {=ROUNDUP(Q23+R23,0)} -> 3 | T23: 검측
C24: 보슬라브 철근조립 | D24: ton | E24: 30.45 | F24: 0.7 | G24: {=ROUNDUP(E24/F24,0)} -> 44 | H24: {=ROUNDUP(G24/Q24,0)} -> 15 | I24: 일수고정 | J24: 3 | K24: 18 | L24: {=N24/J24} -> 7 | M24: 1.2 | N24: {=ROUND(M24*K24/J24,0)*J24} -> 21 | Q24: 3 | R24: 0.5 | S24: {=ROUNDUP(Q24+R24,0)} -> 4 | T24: 검측
C25: 피트층 타설 | D25: ㎥ | E25: 498.8 | F25: 130 | G25: {=H25*Q25} -> 5 | H25: {=P25*5} -> 5 | I25: 장비대수*5명 /지하골조부분 | M25: 1 | O25: 콘크리트 펌프차 | P25: {=CEILING(MIN(2,E25/'타설 '!B4),1)} -> 1 | Q25: {=MAX(1,IF(E25/(F25*H25)-INT(E25/(F25*H25))<0.5,ROUNDDOWN(E25/(F25*H25),0),ROUNDUP(E25/(F25*H25),0)))} -> 1 | R25: 3 | S25: {=ROUNDUP(Q25+R25,0)} -> 4 | T25: 양생
C26: 거푸집 해체/정리 | D26: ㎡ | E26: {=E18+E20+E23} -> 5072 | F26: 50 | G26: {=ROUNDUP(E26/F26,0)} -> 102 | H26: {=ROUNDUP(G26/Q26,0)} -> 5 | I26: 일수고정 | J26: 2 | K26: 26 | L26: {=N26/J26} -> 16 | M26: 1.2 | N26: {=ROUND(M26*K26/J26,0)*J26} -> 32 | Q26: 22 | S26: {=ROUNDUP(Q26+R26,0)} -> 22
A28: 일반층 | C28: 먹매김 | D28: ㎡ | H28: 3 | J28: 3 | K28: 6 | L28: {=N28/J28} -> 2 | M28: 1 | N28: {=ROUND(M28*K28/J28,0)*J28} -> 6 | R28: 1 | S28: {=ROUNDUP(Q28+R28,0)} -> 1 | T28: 검측
C29: 벽 철근조립 | D29: ton | E29: 4.97 | F29: 0.7 | G29: {=ROUNDUP(E29/F29,0)} -> 8 | H29: {=ROUNDUP(G29/Q29,0)} -> 8 | I29: 일수고정 | J29: 3 | K29: 15 | L29: {=N29/J29} -> 4 | M29: 0.85 | N29: {=ROUND(M29*K29/J29,0)*J29} -> 12 | Q29: 1 | R29: 0.5 | S29: {=ROUNDUP(Q29+R29,0)} -> 2 | T29: 검측
C30: 유로폼 설치 | D30: ㎡ | E30: 291 | F30: 9 | G30: {=ROUNDUP(E30/F30,0)} -> 33 | H30: {=ROUNDUP(G30/Q30,0)} -> 6 | I30: 일수고정 | J30: 2 | K30: 10 | L30: {=N30/J30} -> 4 | M30: 0.85 | N30: {=ROUND(M30*K30/J30,0)*J30} -> 8 | Q30: 6 | R30: 0.5 | S30: {=ROUNDUP(Q30+R30,0)} -> 7 | T30: 검측
C31: 보슬라브 철근조립 | D31: ton | E31: 4.97 | F31: 0.6 | G31: {=ROUNDUP(E31/F31,0)} -> 9 | H31: {=ROUNDUP(G31/Q31,0)} -> 9 | I31: 일수고정 | J31: 3 | K31: 18 | L31: {=N31/J31} -> 5 | M31: 0.85 | N31: {=ROUND(M31*K31/J31,0)*J31} -> 15 | Q31: 1 | R31: 0.5 | S31: {=ROUNDUP(Q31+R31,0)} -> 2 | T31: 검측
C32: 타설 | D32: ㎥ | E32: 102 | F32: 130 | G32: {=H32*Q32} -> 5 | H32: {=P32*5} -> 5 | I32: 장비대수*4명 /최상층 | M32: 1 | O32: 콘크리트 펌프차 | P32: {=CEILING(MIN(2,E32/'타설 '!B5),1)} -> 1 | Q32: {=MAX(1,IF(E32/(F32*H32)-INT(E32/(F32*H32))<0.5,ROUNDDOWN(E32/(F32*H32),0),ROUNDUP(E32/(F32*H32),0)))} -> 1 | R32: 2 | S32: {=ROUNDUP(Q32+R32,0)} -> 3 | T32: 양생
C33: 거푸집 해체/정리 | D33: ㎡ | E33: {=E30} -> 291 | F33: 50 | G33: {=ROUNDUP(E33/F33,0)} -> 6 | H33: {=ROUNDUP(G33/Q33,0)} -> 6 | I33: 일수고정 | J33: 2 | K33: 6 | L33: {=N33/J33} -> 4 | M33: 1.2 | N33: {=ROUND(M33*K33/J33,0)*J33} -> 8 | Q33: 1 | S33: {=ROUNDUP(Q33+R33,0)} -> 1
A35: 셋팅층 | C35: 먹매김 | D35: ㎡ | H35: 3 | J35: 3 | K35: 6 | L35: {=N35/J35} -> 2 | M35: 1 | N35: {=ROUND(M35*K35/J35,0)*J35} -> 6 | R35: 1 | S35: {=ROUNDUP(Q35+R35,0)} -> 1 | T35: 검측
C36: 갱폼 설치 | D36: ㎡ | E36: 654.3 | F36: 30 | G36: {=ROUNDUP(E36/F36,0)} -> 22 | H36: {=ROUNDUP(G36/Q36,0)} -> 11 | I36: 일수고정 | J36: 4 | K36: 20 | L36: {=N36/J36} -> 5 | M36: 0.9 | N36: {=ROUND(M36*K36/J36,0)*J36} -> 20 | Q36: 2 | R36: 6 | S36: {=ROUNDUP(Q36+R36,0)} -> 8 | T36: 앵커/안전발판
C37: 벽 철근조립 | D37: ton | E37: 13.21 | F37: 0.8 | G37: {=ROUNDUP(E37/F37,0)} -> 17 | H37: {=ROUNDUP(G37/Q37,0)} -> 9 | I37: 일수고정 | J37: 3 | K37: 15 | L37: {=N37/J37} -> 5 | M37: 0.9 | N37: {=ROUND(M37*K37/J37,0)*J37} -> 15 | Q37: 2 | R37: 0.5 | S37: 2 | T37: 검측
C38: 알폼 조립 | D38: ㎡ | E38: 799.7 | F38: 30 | G38: {=ROUNDUP(E38/F38,0)} -> 27 | H38: {=ROUNDUP(G38/Q38,0)} -> 7 | I38: 일수고정 | J38: 3 | K38: 18 | L38: {=N38/J38} -> 5 | M38: 0.9 | N38: {=ROUND(M38*K38/J38,0)*J38} -> 15 | Q38: 4 | R38: 0.5 | S38: 4 | T38: 검측
C39: 보슬라브 철근조립 | D39: ton | E39: 13.21 | F39: 0.9 | G39: {=ROUNDUP(E39/F39,0)} -> 15 | H39: {=ROUNDUP(G39/Q39,0)} -> 8 | I39: 일수고정 | J39: 3 | K39: 18 | L39: {=N39/J39} -> 5 | M39: 0.9 | N39: {=ROUND(M39*K39/J39,0)*J39} -> 15 | Q39: 2 | R39: 0.5 | S39: 2 | T39: 검측
C40: 타설 | D40: ㎥ | E40: 236 | F40: 130 | G40: {=H40*Q40} -> 5 | H40: {=P40*5} -> 5 | I40: 장비대수*6명 /셋팅층 | M40: 1 | O40: 콘크리트 펌프차 | P40: {=CEILING(MIN(2,E40/'타설 '!B6),1)} -> 1 | Q40: {=MAX(1,IF(E40/(F40*H40)-INT(E40/(F40*H40))<0.5,ROUNDDOWN(E40/(F40*H40),0),ROUNDUP(E40/(F40*H40),0)))} -> 1 | R40: 2 | S40: {=ROUNDUP(Q40+R40,0)} -> 3 | T40: 양생
A42: 기준층 | C42: 먹매김 | D42: ㎡ | H42: 3 | J42: 3 | K42: 6 | L42: {=N42/J42} -> 2 | M42: 1 | N42: {=ROUND(M42*K42/J42,0)*J42} -> 6 | R42: 1 | S42: {=ROUNDUP(Q42+R42,0)} -> 1 | T42: 검측
C43: 갱폼 설치 | D43: ㎡ | E43: 778.95 | F43: 60 | G43: {=ROUNDUP(E43/F43,0)} -> 13 | H43: {=ROUNDUP(G43/Q43,0)} -> 13 | I43: 일수고정 | J43: 4 | K43: 20 | L43: {=N43/J43} -> 5 | M43: 1 | N43: {=ROUND(M43*K43/J43,0)*J43} -> 20 | Q43: 1 | R43: 1 | S43: {=ROUNDUP(Q43+R43,0)} -> 2 | T43: 보강/검측
C44: 벽 철근조립 | D44: ton | E44: 9.42 | F44: 0.8 | G44: {=ROUNDUP(E44/F44,0)} -> 12 | H44: {=ROUNDUP(G44/Q44,0)} -> 12 | I44: 일수고정 | J44: 3 | K44: 15 | L44: {=N44/J44} -> 5 | M44: 1 | N44: {=ROUND(M44*K44/J44,0)*J44} -> 15 | Q44: 1 | R44: 0.5 | S44: {=ROUNDUP(Q44+R44,0)} -> 2 | T44: 검측
...

Sheet 주동지하
A1: 구분 | B1: 층수 | C1: 세부공종 | D1: 단위 | E1: 수량 | F1: 인당 생산성 | G1: 총 투입인원 | H1: 1일 투입인원 | I1: 산정 기준 | J1: 작업조 기준인원 | K1: 기준 인원 | L1: 최대 작업조 | M1: 부분별 보정계수 | N1: 최대투입인원 | O1: 투입장비명 | P1: 장비대수 | Q1: 순작업일 | R1: 간접일 | S1: 총작업일수 | T1: 간접작업항목
A2: 버림 | C2: 버림틀설치 | D2: ㎡ | E2: 40 | F2: 10 | G2: {=E2/F2} -> 4 | H2: {=ROUNDUP(G2/Q2,0)} -> 4 | I2: 일수고정 | J2: 2 | K2: 6 | L2: {=N2/J2} -> 3 | M2: {=1} -> 1 | N2: {=ROUND(M2*K2/J2,0)*J2} -> 6 | Q2: 1 | S2: {=ROUNDUP(Q2+R2,0)} -> 1
C3: 버림타설 | D3: ㎥ | E3: 228 | F3: 130 | G3: {=H3*Q3} -> 5 | H3: {=P3*5} -> 5 | I3: 장비대수*4명 /버림부분 | M3: 1 | O3: 콘크리트 펌프차 | P3: {=CEILING(MIN(2,E3/'타설 '!B2),1)} -> 1 | Q3: {=MAX(1,IF(E3/(F3*H3)-INT(E3/(F3*H3))<0.5,ROUNDDOWN(E3/(F3*H3),0),ROUNDUP(E3/(F3*H3),0)))} -> 1 | R3: 1 | S3: {=ROUNDUP(Q3+R3,0)} -> 2 | T3: 양생
A4: 기초 | C4: 먹매김 | D4: ㎡ | H4: 3 | I4: 일수고정 | J4: 3 | K4: 6 | L4: {=N4/J4} -> 2 | M4: 1 | N4: {=ROUND(M4*K4/J4,0)*J4} -> 6 | Q4: 1 | S4: {=ROUNDUP(Q4+R4,0)} -> 1
C5: 기초철근조립 | D5: ton | E5: 110.62 | F5: 1.1 | G5: {=ROUNDUP(E5/F5,0)} -> 101 | H5: {=ROUNDUP(G5/Q5,0)} -> 17 | I5: 일수고정 | J5: 4 | K5: 24 | L5: {=N5/J5} -> 8 | M5: 1.3 | N5: {=ROUND(M5*K5/J5,0)*J5} -> 32 | Q5: 6 | R5: 0.5 | S5: {=ROUNDUP(Q5+R5,0)} -> 7 | T5: 검측
C6: 끊어치기 작업 | D6: ㎡ | E6: 120 | F6: 10 | G6: {=ROUNDUP(E6/F6,0)} -> 12 | H6: {=ROUNDUP(G6/Q6,0)} -> 6 | I6: 일수고정 | J6: 3 | K6: 6 | L6: {=N6/J6} -> 2 | M6: 1 | N6: {=ROUND(M6*K6/J6,0)*J6} -> 6 | Q6: 2 | R6: 0.5 | S6: {=ROUNDUP(Q6+R6,0)} -> 3 | T6: 검측
C7: 기초타설 | D7: ㎥ | E7: 1643 | F7: 130 | G7: {=H7*Q7} -> 10 | H7: {=P7*5} -> 10 | I7: 장비대수*5명 /기초부분 | M7: 1 | O7: 콘크리트 펌프차 | P7: {=CEILING(MIN(2,E7/'타설 '!B3),1)} -> 2 | Q7: {=MAX(1,IF(E7/(F7*H7)-INT(E7/(F7*H7))<0.5,ROUNDDOWN(E7/(F7*H7),0),ROUNDUP(E7/(F7*H7),0)))} -> 1 | R7: 3 | S7: {=ROUNDUP(Q7+R7,0)} -> 4 | T7: 양생
A9: 지하층 | B9: B2 | C9: 먹매김 | D9: ㎡ | H9: 3 | I9: 일수고정 | J9: 3 | K9: 6 | L9: {=N9/J9} -> 2 | M9: 1 | N9: {=ROUND(M9*K9/J9,0)*J9} -> 6 | Q9: 1 | S9: {=ROUNDUP(Q9+R9,0)} -> 1
C10: 벽 철근조립 | D10: ton | E10: 53.1 | F10: 0.8 | G10: {=ROUNDUP(E10/F10,0)} -> 67 | H10: {=ROUNDUP(G10/Q10,0)} -> 14 | I10: 일수고정 | J10: 3 | K10: 18 | L10: {=N10/J10} -> 7 | M10: 1.2 | N10: {=ROUND(M10*K10/J10,0)*J10} -> 21 | Q10: 5 | R10: 0.5 | S10: {=ROUNDUP(Q10+R10,0)} -> 6 | T10: 검측
C11: 지하2층 거푸집 설치 | D11: ㎡ | E11: 4612.25 | F11: 11 | G11: {=ROUNDUP(E11/F11,0)} -> 420 | H11: {=ROUNDUP(G11/Q11,0)} -> 25 | I11: 일수고정 | J11: 2 | K11: 16 | L11: {=N11/J11} -> 10 | M11: 1.2 | N11: {=ROUND(M11*K11/J11,0)*J11} -> 20 | Q11: 17 | R11: 1 | S11: {=ROUNDUP(Q11+R11,0)} -> 18 | T11: 보강/검측
C12: 보슬라브 철근조립 | D12: ton | E12: 64.91 | F12: 0.8 | G12: {=ROUNDUP(E12/F12,0)} -> 82 | H12: {=ROUNDUP(G12/Q12,0)} -> 17 | I12: 일수고정 | J12: 3 | K12: 18 | L12: {=N12/J12} -> 7 | M12: 1.2 | N12: {=ROUND(M12*K12/J12,0)*J12} -> 21 | Q12: 5 | R12: 0.5 | S12: {=ROUNDUP(Q12+R12,0)} -> 6 | T12: 검측
C13: 마감작업 | D13: ㎡ | E13: 242.75 | F13: 11 | G13: {=ROUNDUP(E13/F13,0)} -> 23 | H13: {=ROUNDUP(G13/Q13,0)} -> 12 | I13: 일수고정 | J13: 2 | K13: 12 | L13: {=N13/J13} -> 7 | M13: 1.2 | N13: {=ROUND(M13*K13/J13,0)*J13} -> 14 | Q13: 2 | R13: 0.5 | S13: {=ROUNDUP(Q13+R13,0)} -> 3 | T13: 검측
C14: 타설 | D14: ㎥ | E14: 782 | F14: 130 | G14: {=H14*Q14} -> 10 | H14: {=P14*5} -> 10 | I14: 장비대수*5명 /지하골조부분 | M14: 1 | O14: 콘크리트 펌프차 | P14: {=CEILING(MIN(2,E14/'타설 '!B4),1)} -> 2 | Q14: {=MAX(1,IF(E14/(F14*H14)-INT(E14/(F14*H14))<0.5,ROUNDDOWN(E14/(F14*H14),0),ROUNDUP(E14/(F14*H14),0)))} -> 1 | R14: 3 | S14: {=ROUNDUP(Q14+R14,0)} -> 4 | T14: 양생
C15: 거푸집 해체/정리 | D15: ㎡ | E15: {=E11+E13} -> 4855 | F15: 50 | G15: {=ROUNDUP(E15/F15,0)} -> 98 | H15: {=ROUNDUP(G15/Q15,0)} -> 7 | I15: 일수고정 | J15: 2 | K15: 24 | L15: {=N15/J15} -> 14 | M15: 1.2 | N15: {=ROUND(M15*K15/J15,0)*J15} -> 28 | Q15: 16 | S15: {=ROUNDUP(Q15+R15,0)} -> 16
A16: 지하층 | B16: B1 | C16: 먹매김 | D16: ㎡ | H16: 3 | I16: 일수고정 | J16: 3 | K16: 6 | L16: {=N16/J16} -> 2 | M16: 1 | N16: {=ROUND(M16*K16/J16,0)*J16} -> 6 | R16: 1 | S16: {=ROUNDUP(Q16+R16,0)} -> 1
C17: 벽 철근조립 | D17: ton | E17: 45.68 | F17: 0.7 | G17: {=ROUNDUP(E17/F17,0)} -> 66 | H17: {=ROUNDUP(G17/Q17,0)} -> 14 | I17: 일수고정 | J17: 3 | K17: 18 | L17: {=N17/J17} -> 7 | M17: 1.2 | N17: {=ROUND(M17*K17/J17,0)*J17} -> 21 | Q17: 5 | R17: 0.5 | S17: {=ROUNDUP(Q17+R17,0)} -> 6 | T17: 검측
C18: 지하1층 거푸집 설치 | D18: ㎡ | E18: 4564.8 | F18: 9 | G18: {=ROUNDUP(E18/F18,0)} -> 508 | H18: {=ROUNDUP(G18/Q18,0)} -> 27 | I18: 일수고정 | J18: 2 | K18: 10 | L18: {=N18/J18} -> 6 | M18: 1.2 | N18: {=ROUND(M18*K18/J18,0)*J18} -> 12 | Q18: 19 | R18: 0.5 | S18: {=ROUNDUP(Q18+R18,0)} -> 20 | T18: 검측
C19: 보슬라브 철근조립 | D19: ton | E19: 45.68 | F19: 0.7 | G19: {=ROUNDUP(E19/F19,0)} -> 66 | H19: {=ROUNDUP(G19/Q19,0)} -> 14 | I19: 일수고정 | J19: 3 | K19: 18 | L19: {=N19/J19} -> 7 | M19: 1.2 | N19: {=ROUND(M19*K19/J19,0)*J19} -> 21 | Q19: 5 | R19: 0.5 | S19: {=ROUNDUP(Q19+R19,0)} -> 6 | T19: 검측
C20: 마감작업 | D20: ㎡ | E20: 253.6 | F20: 10 | G20: {=ROUNDUP(E20/F20,0)} -> 26 | H20: {=ROUNDUP(G20/Q20,0)} -> 13 | I20: 일수고정 | J20: 2 | K20: 24 | L20: {=N20/J20} -> 14 | M20: 1.2 | N20: {=ROUND(M20*K20/J20,0)*J20} -> 28 | Q20: 2 | R20: 0.5 | S20: {=ROUNDUP(Q20+R20,0)} -> 3 | T20: 검측
C21: 타설 | D21: ㎥ | E21: 748.2 | F21: 130 | G21: {=H21*Q21} -> 10 | H21: {=P21*5} -> 10 | I21: 장비대수*5명 /지하골조부분 | M21: 1 | O21: 콘크리트 펌프차 | P21: {=CEILING(MIN(2,E21/'타설 '!B4),1)} -> 2 | Q21: {=MAX(1,IF(E21/(F21*H21)-INT(E21/(F21*H21))<0.5,ROUNDDOWN(E21/(F21*H21),0),ROUNDUP(E21/(F21*H21),0)))} -> 1 | R21: 3 | S21: {=ROUNDUP(Q21+R21,0)} -> 4 | T21: 양생
C22: 벽 철근조립 | D22: ton | E22: 30.45 | F22: 0.7 | G22: {=ROUNDUP(E22/F22,0)} -> 44 | H22: {=ROUNDUP(G22/Q22,0)} -> 15 | I22: 일수고정 | J22: 3 | K22: 18 | L22: {=N22/J22} -> 7 | M22: 1.2 | N22: {=ROUND(M22*K22/J22,0)*J22} -> 21 | Q22: 3 | R22: 0.5 | S22: {=ROUNDUP(Q22+R22,0)} -> 4 | T22: 검측
C23: 피트층 거푸집 설치 | D23: ㎡ | E23: 253.6 | F23: 10 | G23: {=ROUNDUP(E23/F23,0)} -> 26 | H23: {=ROUNDUP(G23/Q23,0)} -> 13 | I23: 일수고정 | J23: 2 | K23: 24 | L23: {=N23/J23} -> 14 | M23: 1.2 | N23: {=ROUND(M23*K23/J23,0)*J23} -> 28 | Q23: 2 | R23: 0.5 | S23: {=ROUNDUP(Q23+R23,0)} -> 3 | T23: 검측
C24: 보슬라브 철근조립 | D24: ton | E24: 30.45 | F24: 0.7 | G24: {=ROUNDUP(E24/F24,0)} -> 44 | H24: {=ROUNDUP(G24/Q24,0)} -> 15 | I24: 일수고정 | J24: 3 | K24: 18 | L24: {=N24/J24} -> 7 | M24: 1.2 | N24: {=ROUND(M24*K24/J24,0)*J24} -> 21 | Q24: 3 | R24: 0.5 | S24: {=ROUNDUP(Q24+R24,0)} -> 4 | T24: 검측
C25: 피트층 타설 | D25: ㎥ | E25: 498.8 | F25: 130 | G25: {=H25*Q25} -> 5 | H25: {=P25*5} -> 5 | I25: 장비대수*5명 /지하골조부분 | M25: 1 | O25: 콘크리트 펌프차 | P25: {=CEILING(MIN(2,E25/'타설 '!B4),1)} -> 1 | Q25: {=MAX(1,IF(E25/(F25*H25)-INT(E25/(F25*H25))<0.5,ROUNDDOWN(E25/(F25*H25),0),ROUNDUP(E25/(F25*H25),0)))} -> 1 | R25: 3 | S25: {=ROUNDUP(Q25+R25,0)} -> 4 | T25: 양생
C26: 거푸집 해체/정리 | D26: ㎡ | E26: {=E18+E20+E23} -> 5072 | F26: 50 | G26: {=ROUNDUP(E26/F26,0)} -> 102 | H26: {=ROUNDUP(G26/Q26,0)} -> 5 | I26: 일수고정 | J26: 2 | K26: 26 | L26: {=N26/J26} -> 16 | M26: 1.2 | N26: {=ROUND(M26*K26/J26,0)*J26} -> 32 | Q26: 22 | S26: {=ROUNDUP(Q26+R26,0)} -> 22

Sheet 지하주차장
A1: 구분 | B1: 층수 | C1: 세부공종 | D1: 단위 | E1: 수량 | F1: 인당 생산성 | G1: 총 투입인원 | H1: 1일 투입인원 | I1: 산정 기준 | J1: 작업조 기준인원 | K1: 기준 인원 | L1: 최대 작업조 | M1: 부분별 보정계수 | N1: 최대투입인원 | O1: 투입장비명 | P1: 장비대수 | Q1: 순작업일 | R1: 간접일 | S1: 총작업일수 | T1: 간접작업항목
A2: 버림 | C2: 버림틀설치 | D2: ㎡ | E2: 40 | F2: 10 | G2: {=E2/F2} -> 4 | H2: {=ROUNDUP(G2/Q2,0)} -> 4 | I2: 일수고정 | J2: 2 | K2: 6 | L2: {=N2/J2} -> 3 | M2: {=1} -> 1 | N2: {=ROUND(M2*K2/J2,0)*J2} -> 6 | Q2: 1 | S2: {=ROUNDUP(Q2+R2,0)} -> 1
C3: 버림타설 | D3: ㎥ | E3: 228 | F3: 130 | G3: {=H3*Q3} -> 5 | H3: {=P3*5} -> 5 | I3: 장비대수*4명 /버림부분 | M3: 1 | O3: 콘크리트 펌프차 | P3: {=CEILING(MIN(2,E3/'타설 '!B2),1)} -> 1 | Q3: {=MAX(1,IF(E3/(F3*H3)-INT(E3/(F3*H3))<0.5,ROUNDDOWN(E3/(F3*H3),0),ROUNDUP(E3/(F3*H3),0)))} -> 1 | R3: 1 | S3: {=ROUNDUP(Q3+R3,0)} -> 2 | T3: 양생
A4: 기초 | C4: 먹매김 | D4: ㎡ | H4: 3 | I4: 일수고정 | J4: 3 | K4: 6 | L4: {=N4/J4} -> 2 | M4: 1 | N4: {=ROUND(M4*K4/J4,0)*J4} -> 6 | Q4: 1 | S4: {=ROUNDUP(Q4+R4,0)} -> 1
C5: 기초철근조립 | D5: ton | E5: 110.62 | F5: 1.1 | G5: {=ROUNDUP(E5/F5,0)} -> 101 | H5: {=ROUNDUP(G5/Q5,0)} -> 17 | I5: 일수고정 | J5: 4 | K5: 24 | L5: {=N5/J5} -> 8 | M5: 1.3 | N5: {=ROUND(M5*K5/J5,0)*J5} -> 32 | Q5: 6 | R5: 0.5 | S5: {=ROUNDUP(Q5+R5,0)} -> 7 | T5: 검측
C6: 끊어치기 작업 | D6: ㎡ | E6: 120 | F6: 10 | G6: {=ROUNDUP(E6/F6,0)} -> 12 | H6: {=ROUNDUP(G6/Q6,0)} -> 6 | I6: 일수고정 | J6: 3 | K6: 6 | L6: {=N6/J6} -> 2 | M6: 1 | N6: {=ROUND(M6*K6/J6,0)*J6} -> 6 | Q6: 2 | R6: 0.5 | S6: {=ROUNDUP(Q6+R6,0)} -> 3 | T6: 검측
C7: 기초타설 | D7: ㎥ | E7: 1643 | F7: 130 | G7: {=H7*Q7} -> 10 | H7: {=P7*5} -> 10 | I7: 장비대수*5명 /기초부분 | M7: 1 | O7: 콘크리트 펌프차 | P7: {=CEILING(MIN(2,E7/'타설 '!B3),1)} -> 2 | Q7: {=MAX(1,IF(E7/(F7*H7)-INT(E7/(F7*H7))<0.5,ROUNDDOWN(E7/(F7*H7),0),ROUNDUP(E7/(F7*H7),0)))} -> 1 | R7: 3 | S7: {=ROUNDUP(Q7+R7,0)} -> 4 | T7: 양생
A9: 지하층 | B9: B2 | C9: 먹매김 | D9: ㎡ | H9: 3 | I9: 일수고정 | J9: 3 | K9: 6 | L9: {=N9/J9} -> 2 | M9: 1 | N9: {=ROUND(M9*K9/J9,0)*J9} -> 6 | Q9: 1 | S9: {=ROUNDUP(Q9+R9,0)} -> 1
C10: 벽 철근조립 | D10: ton | E10: 53.1 | F10: 0.8 | G10: {=ROUNDUP(E10/F10,0)} -> 67 | H10: {=ROUNDUP(G10/Q10,0)} -> 14 | I10: 일수고정 | J10: 3 | K10: 18 | L10: {=N10/J10} -> 7 | M10: 1.2 | N10: {=ROUND(M10*K10/J10,0)*J10} -> 21 | Q10: 5 | R10: 0.5 | S10: {=ROUNDUP(Q10+R10,0)} -> 6 | T10: 검측
C11: 지하2층 거푸집 설치 | D11: ㎡ | E11: 4612.25 | F11: 11 | G11: {=ROUNDUP(E11/F11,0)} -> 420 | H11: {=ROUNDUP(G11/Q11,0)} -> 25 | I11: 일수고정 | J11: 2 | K11: 16 | L11: {=N11/J11} -> 10 | M11: 1.2 | N11: {=ROUND(M11*K11/J11,0)*J11} -> 20 | Q11: 17 | R11: 1 | S11: {=ROUNDUP(Q11+R11,0)} -> 18 | T11: 보강/검측
C12: 보슬라브 철근조립 | D12: ton | E12: 64.91 | F12: 0.8 | G12: {=ROUNDUP(E12/F12,0)} -> 82 | H12: {=ROUNDUP(G12/Q12,0)} -> 17 | I12: 일수고정 | J12: 3 | K12: 18 | L12: {=N12/J12} -> 7 | M12: 1.2 | N12: {=ROUND(M12*K12/J12,0)*J12} -> 21 | Q12: 5 | R12: 0.5 | S12: {=ROUNDUP(Q12+R12,0)} -> 6 | T12: 검측
C13: 마감작업 | D13: ㎡ | E13: 242.75 | F13: 11 | G13: {=ROUNDUP(E13/F13,0)} -> 23 | H13: {=ROUNDUP(G13/Q13,0)} -> 12 | I13: 일수고정 | J13: 2 | K13: 12 | L13: {=N13/J13} -> 7 | M13: 1.2 | N13: {=ROUND(M13*K13/J13,0)*J13} -> 14 | Q13: 2 | R13: 0.5 | S13: {=ROUNDUP(Q13+R13,0)} -> 3 | T13: 검측
C14: 타설 | D14: ㎥ | E14: 782 | F14: 130 | G14: {=H14*Q14} -> 10 | H14: {=P14*5} -> 10 | I14: 장비대수*5명 /지하골조부분 | M14: 1 | O14: 콘크리트 펌프차 | P14: {=CEILING(MIN(2,E14/'타설 '!B4),1)} -> 2 | Q14: {=MAX(1,IF(E14/(F14*H14)-INT(E14/(F14*H14))<0.5,ROUNDDOWN(E14/(F14*H14),0),ROUNDUP(E14/(F14*H14),0)))} -> 1 | R14: 3 | S14: {=ROUNDUP(Q14+R14,0)} -> 4 | T14: 양생
C15: 거푸집 해체/정리 | D15: ㎡ | E15: {=E11+E13} -> 4855 | F15: 50 | G15: {=ROUNDUP(E15/F15,0)} -> 98 | H15: {=ROUNDUP(G15/Q15,0)} -> 7 | I15: 일수고정 | J15: 2 | K15: 24 | L15: {=N15/J15} -> 14 | M15: 1.2 | N15: {=ROUND(M15*K15/J15,0)*J15} -> 28 | Q15: 16 | S15: {=ROUNDUP(Q15+R15,0)} -> 16
A16: 지하층 | B16: B1 | C16: 먹매김 | D16: ㎡ | H16: 3 | I16: 일수고정 | J16: 3 | K16: 6 | L16: {=N16/J16} -> 2 | M16: 1 | N16: {=ROUND(M16*K16/J16,0)*J16} -> 6 | R16: 1 | S16: {=ROUNDUP(Q16+R16,0)} -> 1
C17: 벽 철근조립 | D17: ton | E17: 45.68 | F17: 0.7 | G17: {=ROUNDUP(E17/F17,0)} -> 66 | H17: {=ROUNDUP(G17/Q17,0)} -> 14 | I17: 일수고정 | J17: 3 | K17: 18 | L17: {=N17/J17} -> 7 | M17: 1.2 | N17: {=ROUND(M17*K17/J17,0)*J17} -> 21 | Q17: 5 | R17: 0.5 | S17: {=ROUNDUP(Q17+R17,0)} -> 6 | T17: 검측
C18: 지하1층 거푸집 설치 | D18: ㎡ | E18: 4564.8 | F18: 9 | G18: {=ROUNDUP(E18/F18,0)} -> 508 | H18: {=ROUNDUP(G18/Q18,0)} -> 27 | I18: 일수고정 | J18: 2 | K18: 10 | L18: {=N18/J18} -> 6 | M18: 1.2 | N18: {=ROUND(M18*K18/J18,0)*J18} -> 12 | Q18: 19 | R18: 0.5 | S18: {=ROUNDUP(Q18+R18,0)} -> 20 | T18: 검측
C19: 보슬라브 철근조립 | D19: ton | E19: 45.68 | F19: 0.7 | G19: {=ROUNDUP(E19/F19,0)} -> 66 | H19: {=ROUNDUP(G19/Q19,0)} -> 14 | I19: 일수고정 | J19: 3 | K19: 18 | L19: {=N19/J19} -> 7 | M19: 1.2 | N19: {=ROUND(M19*K19/J19,0)*J19} -> 21 | Q19: 5 | R19: 0.5 | S19: {=ROUNDUP(Q19+R19,0)} -> 6 | T19: 검측
C20: 마감작업 | D20: ㎡ | E20: 253.6 | F20: 10 | G20: {=ROUNDUP(E20/F20,0)} -> 26 | H20: {=ROUNDUP(G20/Q20,0)} -> 13 | I20: 일수고정 | J20: 2 | K20: 24 | L20: {=N20/J20} -> 14 | M20: 1.2 | N20: {=ROUND(M20*K20/J20,0)*J20} -> 28 | Q20: 2 | R20: 0.5 | S20: {=ROUNDUP(Q20+R20,0)} -> 3 | T20: 검측
C21: 타설 | D21: ㎥ | E21: 748.2 | F21: 130 | G21: {=H21*Q21} -> 10 | H21: {=P21*5} -> 10 | I21: 장비대수*5명 /지하골조부분 | M21: 1 | O21: 콘크리트 펌프차 | P21: {=CEILING(MIN(2,E21/'타설 '!B4),1)} -> 2 | Q21: {=MAX(1,IF(E21/(F21*H21)-INT(E21/(F21*H21))<0.5,ROUNDDOWN(E21/(F21*H21),0),ROUNDUP(E21/(F21*H21),0)))} -> 1 | R21: 3 | S21: {=ROUNDUP(Q21+R21,0)} -> 4 | T21: 양생
C22: 거푸집 해체/정리 | D22: ㎡ | E22: {=E18+E20} -> 4818.4 | F22: 50 | G22: {=ROUNDUP(E22/F22,0)} -> 97 | H22: {=ROUNDUP(G22/Q22,0)} -> 5 | I22: 일수고정 | J22: 2 | K22: 26 | L22: {=N22/J22} -> 16 | M22: 1.2 | N22: {=ROUND(M22*K22/J22,0)*J22} -> 32 | Q22: 22 | S22: {=ROUNDUP(Q22+R22,0)} -> 22

Sheet 층고 6.5m 이상
A1: 구분 | B1: 층수 | C1: 세부공종 | D1: 단위 | E1: 수량 | F1: 인당 생산성 | G1: 총 투입인원 | H1: 1일 투입인원 | I1: 산정 기준 | J1: 작업조 기준인원 | K1: 기준 인원 | L1: 최대 작업조 | M1: 부분별 보정계수 | N1: 최대투입인원 | O1: 투입장비명 | P1: 장비대수 | Q1: 순작업일 | R1: 간접일 | S1: 총작업일수 | T1: 간접작업항목
A2: 버림 | C2: 버림틀설치 | D2: ㎡ | E2: 40 | F2: 10 | G2: {=E2/F2} -> 4 | H2: {=ROUNDUP(G2/Q2,0)} -> 4 | I2: 일수고정 | J2: 2 | K2: 6 | L2: {=N2/J2} -> 3 | M2: {=1} -> 1 | N2: {=ROUND(M2*K2/J2,0)*J2} -> 6 | Q2: 1 | S2: {=ROUNDUP(Q2+R2,0)} -> 1
C3: 버림타설 | D3: ㎥ | E3: 228 | F3: 130 | G3: {=H3*Q3} -> 5 | H3: {=P3*5} -> 5 | I3: 장비대수*4명 /버림부분 | M3: 1 | O3: 콘크리트 펌프차 | P3: {=CEILING(MIN(2,E3/'타설 '!B2),1)} -> 1 | Q3: {=MAX(1,IF(E3/(F3*H3)-INT(E3/(F3*H3))<0.5,ROUNDDOWN(E3/(F3*H3),0),ROUNDUP(E3/(F3*H3),0)))} -> 1 | R3: 1 | S3: {=ROUNDUP(Q3+R3,0)} -> 2 | T3: 양생
A4: 기초 | C4: 먹매김 | D4: ㎡ | H4: 3 | I4: 일수고정 | J4: 3 | K4: 6 | L4: {=N4/J4} -> 2 | M4: 1 | N4: {=ROUND(M4*K4/J4,0)*J4} -> 6 | Q4: 1 | S4: {=ROUNDUP(Q4+R4,0)} -> 1
C5: 기초철근조립 | D5: ton | E5: 110.62 | F5: 1.1 | G5: {=ROUNDUP(E5/F5,0)} -> 101 | H5: {=ROUNDUP(G5/Q5,0)} -> 17 | I5: 일수고정 | J5: 4 | K5: 24 | L5: {=N5/J5} -> 8 | M5: 1.3 | N5: {=ROUND(M5*K5/J5,0)*J5} -> 32 | Q5: 6 | R5: 0.5 | S5: {=ROUNDUP(Q5+R5,0)} -> 7 | T5: 검측
C6: 끊어치기 작업 | D6: ㎡ | E6: 120 | F6: 10 | G6: {=ROUNDUP(E6/F6,0)} -> 12 | H6: {=ROUNDUP(G6/Q6,0)} -> 6 | I6: 일수고정 | J6: 3 | K6: 6 | L6: {=N6/J6} -> 2 | M6: 1 | N6: {=ROUND(M6*K6/J6,0)*J6} -> 6 | Q6: 2 | R6: 0.5 | S6: {=ROUNDUP(Q6+R6,0)} -> 3 | T6: 검측
C7: 기초타설 | D7: ㎥ | E7: 1643 | F7: 130 | G7: {=H7*Q7} -> 10 | H7: {=P7*5} -> 10 | I7: 장비대수*5명 /기초부분 | M7: 1 | O7: 콘크리트 펌프차 | P7: {=CEILING(MIN(2,E7/'타설 '!B3),1)} -> 2 | Q7: {=MAX(1,IF(E7/(F7*H7)-INT(E7/(F7*H7))<0.5,ROUNDDOWN(E7/(F7*H7),0),ROUNDUP(E7/(F7*H7),0)))} -> 1 | R7: 3 | S7: {=ROUNDUP(Q7+R7,0)} -> 4 | T7: 양생
A9: 지하층 | B9: 층고 6.5m 이상 | C9: 먹매김 | D9: ㎡ | H9: 3 | I9: 일수고정 | J9: 3 | K9: 6 | L9: {=N9/J9} -> 2 | M9: 1 | N9: {=ROUND(M9*K9/J9,0)*J9} -> 6 | Q9: 1 | S9: {=ROUNDUP(Q9+R9,0)} -> 1
C10: 벽 철근조립 | D10: ton | E10: 53.1 | F10: 0.8 | G10: {=ROUNDUP(E10/F10,0)} -> 67 | H10: {=ROUNDUP(G10/Q10,0)} -> 14 | I10: 일수고정 | J10: 3 | K10: 18 | L10: {=N10/J10} -> 7 | M10: 1.2 | N10: {=ROUND(M10*K10/J10,0)*J10} -> 21 | Q10: 5 | R10: 0.5 | S10: {=ROUNDUP(Q10+R10,0)} -> 6 | T10: 검측
C11: 시스템동바리 | D11: ㎡ | E11: 400 | F11: 20 | G11: {=ROUNDUP(E11/F11,0)} -> 20 | H11: {=ROUNDUP(G11/Q11,0)} -> 4 | J11: 5 | K11: 25 | L11: {=N11/J11} -> 6 | M11: 1.2 | N11: {=ROUND(M11*K11/J11,0)*J11} -> 30 | Q11: 6 | S11: {=ROUNDUP(Q11+R11,0)} -> 6
C12: 거푸집 설치 | D12: ㎡ | E12: 4612.25 | F12: 11 | G12: {=ROUNDUP(E12/F12,0)} -> 420 | H12: {=ROUNDUP(G12/Q12,0)} -> 25 | I12: 일수고정 | J12: 2 | K12: 16 | L12: {=N12/J12} -> 10 | M12: 1.2 | N12: {=ROUND(M12*K12/J12,0)*J12} -> 20 | Q12: 17 | R12: 1 | S12: {=ROUNDUP(Q12+R12,0)} -> 18 | T12: 보강/검측
C13: 보슬라브 철근조립 | D13: ton | E13: 64.91 | F13: 0.8 | G13: {=ROUNDUP(E13/F13,0)} -> 82 | H13: {=ROUNDUP(G13/Q13,0)} -> 17 | I13: 일수고정 | J13: 3 | K13: 18 | L13: {=N13/J13} -> 7 | M13: 1.2 | N13: {=ROUND(M13*K13/J13,0)*J13} -> 21 | Q13: 5 | R13: 0.5 | S13: {=ROUNDUP(Q13+R13,0)} -> 6 | T13: 검측
C14: 마감작업 | D14: ㎡ | E14: 242.75 | F14: 11 | G14: {=ROUNDUP(E14/F14,0)} -> 23 | H14: {=ROUNDUP(G14/Q14,0)} -> 12 | I14: 일수고정 | J14: 2 | K14: 12 | L14: {=N14/J14} -> 7 | M14: 1.2 | N14: {=ROUND(M14*K14/J14,0)*J14} -> 14 | Q14: 2 | R14: 0.5 | S14: {=ROUNDUP(Q14+R14,0)} -> 3 | T14: 검측
C15: 타설 | D15: ㎥ | E15: 782 | F15: 130 | G15: {=H15*Q15} -> 10 | H15: {=P15*5} -> 10 | I15: 장비대수*5명 /지하골조부분 | M15: 1 | O15: 콘크리트 펌프차 | P15: {=CEILING(MIN(2,E15/'타설 '!B4),1)} -> 2 | Q15: {=MAX(1,IF(E15/(F15*H15)-INT(E15/(F15*H15))<0.5,ROUNDDOWN(E15/(F15*H15),0),ROUNDUP(E15/(F15*H15),0)))} -> 1 | R15: 3 | S15: {=ROUNDUP(Q15+R15,0)} -> 4 | T15: 양생
C16: 거푸집 해체/정리 | D16: ㎡ | E16: {=E12+E14} -> 4855 | F16: 50 | G16: {=ROUNDUP(E16/F16,0)} -> 98 | H16: {=ROUNDUP(G16/Q16,0)} -> 7 | I16: 일수고정 | J16: 2 | K16: 24 | L16: {=N16/J16} -> 14 | M16: 1.2 | N16: {=ROUND(M16*K16/J16,0)*J16} -> 28 | Q16: 16 | S16: {=ROUNDUP(Q16+R16,0)} -> 16

Sheet 타설 
A1: 타설 항목 | B1: 수량
A2: 버림 | B2: 650
A3: 기초 대당타설량 | B3: 650
A4: 지하 대당타설량 | B4: 500
A5: 일반층 대당타설량 | B5: 200
A6: 1층 대당타설량 | B6: 400
A7: 기준층 대당타설량 | B7: 320
A8: 최상층 대당타설량 | B8: 230
A9: PH층 대당타설량 | B9: 230
A10: 펌프차 대수산정기준 | B10: 동별 최대 2대
