Workbook

Sheet 지상 골조표준공정
J2: 참고자료 | N2: 작업면적기준 | P2: 보정계수 적용 | T2: 참고자료 | V2: 참고자료
B3: 구분 | C3: 층수 | D3: 층고 | E3: 면적 | F3: 세부공종 | G3: 단위 | H3: 수량 | I3: 기준 인당 생산성 | J3: 총 투입인원 | K3: 1일 투입인원 | L3: 산정 기준 | M3: 작업조 기준인원 | N3: 최대 작업조 | O3: 최대 인원 | P3: 보정계수 | Q3: 보정최대작업가능인원 | R3: 투입장비명 | S3: 최대장비대수 | T3: 순작업일 | U3: 최소 순작업일 | V3: 총작업일수 | W3: 최소 총작업일 | X3: 간접일 | Y3: 간접작업항목
B4: 일반층 | D4: =층고!C4 | F4: 먹매김 | G4: ㎡ | H4: 184 | I4: 250 | K4: 3 | M4: =작업조구성!$B$10 | N4: 1 | O4: =M4*N4 | P4: ='부분별 보정계수설정'!$B$10 | Q4: =ROUND(O4*P4/M4, 0)*M4 | T4: 1 | U4: =MAX(1, CEILING(H4/(N4*작업조구성!$D$10), 1)) | V4: =ROUNDUP(T4+X4, 0) | W4: =ROUNDUP(U4+X4, 0) | X4: 1 | Y4: 검측
F5: 벽 철근조립 | G5: ton | H5: =9.93*0.5 | I5: =인당생산성!H23 | J5: =ROUNDUP(H5/I5,0) | K5: =ROUNDUP(J5/T5,0) | M5: =작업조구성!$B$8 | N5: 1 | O5: =M5*N5 | P5: ='부분별 보정계수설정'!$B$5 | Q5: =ROUND(O5*P5/M5, 0)*M5 | T5: 1 | U5: =ROUNDUP(H5/(I5*Q5),0) | V5: =ROUNDUP(T5+X5, 0) | W5: =ROUNDUP(U5+X5, 0) | X5: 0.5 | Y5: 검측
F6: 벽 유로폼 설치 | G6: ㎡ | H6: =582/2 | I6: =인당생산성!H24 | J6: =ROUNDUP(H6/I6,0) | K6: =ROUNDUP(J6/T6,0) | M6: =작업조구성!$B$4 | O6: =M6*N6 | P6: ='부분별 보정계수설정'!$B$5 | Q6: =ROUND(O6*P6/M6, 0)*M6 | T6: 6 | U6: =ROUNDUP(H6/(I6*Q6),0) | V6: =ROUNDUP(T6+X6, 0) | W6: =ROUNDUP(U6+X6, 0) | X6: 0.5 | Y6: 검측
F7: 바닥 유로폼 설치 | G7: ㎡ | H7: =582/2 | I7: =인당생산성!H24 | J7: =ROUNDUP(H7/I7,0) | K7: =ROUNDUP(J7/T7,0) | M7: =작업조구성!$B$4 | O7: =M7*N7 | P7: ='부분별 보정계수설정'!$B$5 | Q7: =ROUND(O7*P7/M7, 0)*M7 | T7: 6 | U7: =ROUNDUP(H7/(I7*Q7),0) | V7: =ROUNDUP(T7+X7, 0) | W7: =ROUNDUP(U7+X7, 0) | X7: 0.5 | Y7: 검측
F8: 슬라브철근 조립 | G8: ton | H8: =9.93*0.5 | I8: =인당생산성!H25 | J8: =ROUNDUP(H8/I8,0) | K8: =ROUNDUP(J8/T8,0) | M8: =작업조구성!$B$9 | N8: =CEILING(H9/2/($H$40*0.001)/200,1) | O8: =M8*N8 | P8: ='부분별 보정계수설정'!$B$5 | Q8: =ROUND(O8*P8/M8, 0)*M8 | T8: 1 | U8: =ROUNDUP(H8/(I8*Q8),0) | V8: =ROUNDUP(T8+X8, 0) | W8: =ROUNDUP(U8+X8, 0) | X8: 0.5 | Y8: 검측
F9: 타설 | G9: ㎥ | H9: 102 | I9: =인당생산성!H26 | J9: =K9*T9 | K9: =S9*4 | L9: 장비대수*6명 /일반층 | M9: 6 | N9: =S9 | O9: =N9*M9 | P9: 1 | Q9: =O9*P9 | R9: 콘크리트 펌프차 | S9: =CEILING(MIN(2, H9/'펌프카 부위별 타설량'!B4), 1) | T9: 1 | U9: =T9 | V9: =ROUNDUP(T9+X9, 0) | W9: =ROUNDUP(U9+X9, 0) | X9: 2 | Y9: 양생
F10: 거푸집해체정리 | G10: ㎡ | H10: =(H7)*2 | I10: 50 | J10: =ROUNDUP(H10/I10,0) | K10: =ROUNDUP(J10/T10,0) | M10: =작업조구성!$B$5 | O10: =M10*N10 | P10: ='부분별 보정계수설정'!$B$4 | Q10: =ROUND(O10*P10/M10, 0)*M10 | T10: 22 | U10: =MAX(1, CEILING(H10/(N10*작업조구성!$D$10), 1)) | V10: =ROUNDUP(T10+X10, 0) | W10: =ROUNDUP(U10+X10, 0)
B11: 셋팅층 | D11: =층고!C5 | F11: 먹매김 | G11: ㎡ | H11: 297.71 | I11: 250 | K11: 3 | M11: =작업조구성!$B$10 | N11: 1 | O11: =M11*N11 | P11: ='부분별 보정계수설정'!$B$10 | Q11: =ROUND(O11*P11/M11, 0)*M11 | T11: 1 | U11: =MAX(1, CEILING(H11/(N11*작업조구성!$D$10), 1)) | V11: =ROUNDUP(T11+X11, 0) | W11: =ROUNDUP(U11+X11, 0) | X11: 1 | Y11: 검측
F12: 갱폼설치 | G12: ㎡ | H12: =1454*0.45 | I12: 60 | J12: =ROUNDUP(H12/I12,0) | K12: =ROUNDUP(J12/T12,0) | M12: =작업조구성!$B$2 | N12: =CEILING((H12/(D11*0.001))/40, 1) | O12: =M12*N12 | P12: ='부분별 보정계수설정'!$B$6 | Q12: =ROUND(O12*P12/M12, 0)*M12 | T12: 2 | U12: =ROUNDUP(H12/(I12*Q12),0) | V12: =ROUNDUP(T12+X12, 0) | W12: =ROUNDUP(U12+X12, 0) | X12: 6 | Y12: 앵커/안전발판
F13: 벽 철근조립 | G13: ton | H13: =26.41*0.5 | I13: =인당생산성!H29 | J13: =ROUNDUP(H13/I13,0) | K13: =ROUNDUP(J13/T13,0) | M13: =작업조구성!$B$8 | N13: =CEILING((H12*0.3)/(D11*0.001*25),1) | O13: =M13*N13 | P13: ='부분별 보정계수설정'!$B$6 | Q13: =ROUND(O13*P13/M13, 0)*M13 | T13: 2 | U13: =ROUNDUP(H13/(I13*Q13),0) | V13: 2 | W13: =ROUNDUP(U13+X13, 0) | X13: 0.5 | Y13: 검측
F14: 알폼조립 | G14: ㎡ | H14: =1454*0.55 | I14: =인당생산성!H30 | J14: =ROUNDUP(H14/I14,0) | K14: =ROUNDUP(J14/T14,0) | M14: =작업조구성!$B$3 | N14: =CEILING((H14*0.5/(D11*0.001))/30, 1) | O14: =M14*N14 | P14: ='부분별 보정계수설정'!$B$6 | Q14: =ROUND(O14*P14/M14, 0)*M14 | T14: 4 | U14: =ROUNDUP(H14/(I14*Q14),0) | V14: 4 | W14: =ROUNDUP(U14+X14, 0) | X14: 0.5 | Y14: 검측
F15: 슬라브철근 조립 | G15: ton | H15: =26.41*0.5 | I15: =인당생산성!H31 | J15: =ROUNDUP(H15/I15,0) | K15: =ROUNDUP(J15/T15,0) | M15: =작업조구성!$B$9 | N15: =CEILING(H16/($H$40*0.001)/200,1) | O15: =M15*N15 | P15: ='부분별 보정계수설정'!$B$6 | Q15: =ROUND(O15*P15/M15, 0)*M15 | T15: 2 | U15: =ROUNDUP(H15/(I15*Q15),0) | V15: 2 | W15: =ROUNDUP(U15+X15, 0) | X15: 0.5 | Y15: 검측
F16: 타설 | G16: ㎥ | H16: 236 | I16: =인당생산성!H32 | J16: =K16*T16 | K16: =S16*6 | L16: 장비대수*6명 /셋팅층 | M16: 6 | N16: =S16 | O16: =N16*M16 | P16: 1 | Q16: =O16*P16 | R16: 콘크리트 펌프차 | S16: =CEILING(MIN(2, H16/'펌프카 부위별 타설량'!B5), 1) | T16: 1 | U16: =T16 | V16: =ROUNDUP(T16+X16, 0) | W16: =ROUNDUP(U16+X16, 0) | X16: 2 | Y16: 양생
B17: 기준층 | D17: =층고!C6 | F17: 먹매김 | G17: ㎡ | H17: 297.71 | I17: 250 | K17: 3 | M17: =작업조구성!$B$10 | N17: 1 | O17: =M17*N17 | P17: ='부분별 보정계수설정'!$B$10 | Q17: =ROUND(O17*P17/M17, 0)*M17 | T17: 1 | U17: =MAX(1, CEILING(H17/(N17*작업조구성!$D$10), 1)) | V17: =ROUNDUP(T17+X17, 0) | W17: =ROUNDUP(U17+X17, 0) | X17: 1 | Y17: 검측
F18: 갱폼설치 | G18: ㎡ | H18: =1731*0.45 | I18: =인당생산성!H34 | J18: =ROUNDUP(H18/I18,0) | K18: =ROUNDUP(J18/T18,0) | M18: =작업조구성!$B$2 | N18: =CEILING((H18/(D17*0.001))/40, 1) | O18: =M18*N18 | P18: ='부분별 보정계수설정'!$B$7 | Q18: =ROUND(O18*P18/M18, 0)*M18 | T18: 1 | U18: =ROUNDUP(H18/(I18*Q18),0) | V18: =ROUNDUP(T18+X18, 0) | W18: =ROUNDUP(U18+X18, 0) | X18: 1 | Y18: 보강/검측
F19: 벽 철근조립 | G19: ton | H19: =18.83*0.5 | I19: 0.8 | J19: =ROUNDUP(H19/I19,0) | K19: =ROUNDUP(J19/T19,0) | M19: =작업조구성!$B$8 | N19: =CEILING((H18*0.3)/(D17*0.001*25),1) | O19: =M19*N19 | P19: ='부분별 보정계수설정'!$B$7 | Q19: =ROUND(O19*P19/M19, 0)*M19 | T19: 1 | U19: =ROUNDUP(H19/(I19*Q19),0) | V19: =ROUNDUP(T19+X19, 0) | W19: =ROUNDUP(U19+X19, 0) | X19: 0.5 | Y19: 검측
F20: 알폼조립 | G20: ㎡ | H20: =1731*0.55 | I20: =인당생산성!H36 | J20: =ROUNDUP(H20/I20,0) | K20: =ROUNDUP(J20/T20,0) | M20: =작업조구성!$B$3 | N20: =CEILING((H20*0.5/(D17*0.001))/30, 1) | O20: =M20*N20 | P20: ='부분별 보정계수설정'!$B$7 | Q20: =ROUND(O20*P20/M20, 0)*M20 | T20: 1 | U20: =ROUNDUP(H20/(I20*Q20),0) | V20: =ROUNDUP(T20+X20, 0) | W20: =ROUNDUP(U20+X20, 0) | X20: 0.5 | Y20: 검측
F21: 슬라브철근 조립 | G21: ton | H21: =18.83*0.5 | I21: =인당생산성!H37 | J21: =ROUNDUP(H21/I21,0) | K21: =ROUNDUP(J21/T21,0) | M21: =작업조구성!$B$9 | N21: =CEILING(H22/($H$40*0.001)/200,1) | O21: =M21*N21 | P21: ='부분별 보정계수설정'!$B$7 | Q21: =ROUND(O21*P21/M21, 0)*M21 | T21: 1 | U21: =ROUNDUP(H21/(I21*Q21),0) | V21: =ROUNDUP(T21+X21, 0) | W21: =ROUNDUP(U21+X21, 0) | X21: 0.5 | Y21: 검측
F22: 타설 | G22: ㎥ | H22: 224 | I22: =인당생산성!H38 | J22: =K22*T22 | K22: =S22*6 | L22: 장비대수*4명 /기준층 | M22: 4 | N22: =S22 | O22: =N22*M22 | P22: 1 | Q22: =O22*P22 | R22: 콘크리트 펌프차 | S22: =CEILING(MIN(2, H22/'펌프카 부위별 타설량'!B6), 1) | T22: 1 | U22: =T22 | V22: =ROUNDUP(T22+X22, 0) | W22: =ROUNDUP(U22+X22, 0) | X22: 2 | Y22: 양생
B23: 최상층 | D23: =층고!C7 | F23: 먹매김 | G23: ㎡ | H23: 297.71 | I23: 250 | K23: 3 | M23: =작업조구성!$B$10 | N23: 1 | O23: =M23*N23 | P23: ='부분별 보정계수설정'!$B$10 | Q23: =ROUND(O23*P23/M23, 0)*M23 | T23: 1 | U23: =MAX(1, CEILING(H23/(N23*작업조구성!$D$10), 1)) | V23: =ROUNDUP(T23+X23, 0) | W23: =ROUNDUP(U23+X23, 0) | X23: 1 | Y23: 검측
F24: 갱폼설치 | G24: ㎡ | H24: =1731*0.45 | I24: =인당생산성!H40 | J24: =ROUNDUP(H24/I24,0) | K24: =ROUNDUP(J24/T24,0) | M24: =작업조구성!$B$2 | N24: =CEILING((H24/(D23*0.001))/40, 1) | O24: =M24*N24 | P24: ='부분별 보정계수설정'!$B$8 | Q24: =ROUND(O24*P24/M24, 0)*M24 | T24: 1 | U24: =ROUNDUP(H24/(I24*Q24),0) | V24: =ROUNDUP(T24+X24, 0) | W24: =ROUNDUP(U24+X24, 0) | X24: 1 | Y24: 보강/검측
F25: 벽 철근조립 | G25: ton | H25: =18.83*0.5 | I25: 0.8 | J25: =ROUNDUP(H25/I25,0) | K25: =ROUNDUP(J25/T25,0) | M25: =작업조구성!$B$8 | N25: =CEILING((H24*0.3)/(D23*0.001*19),1) | O25: =M25*N25 | P25: ='부분별 보정계수설정'!$B$8 | Q25: =ROUND(O25*P25/M25, 0)*M25 | T25: 1 | U25: =ROUNDUP(H25/(I25*Q25),0) | V25: =ROUNDUP(T25+X25, 0) | W25: =ROUNDUP(U25+X25, 0) | X25: 0.5 | Y25: 검측
F26: 알폼조립 | G26: ㎡ | H26: =1731*0.55 | I26: =인당생산성!H42 | J26: =ROUNDUP(H26/I26,0) | K26: =ROUNDUP(J26/T26,0) | M26: =작업조구성!$B$3 | N26: =CEILING((H26*0.5/(D23*0.001))/30, 1) | O26: =M26*N26 | P26: ='부분별 보정계수설정'!$B$8 | Q26: =ROUND(O26*P26/M26, 0)*M26 | T26: 1 | U26: =ROUNDUP(H26/(I26*Q26),0) | V26: =ROUNDUP(T26+X26, 0) | W26: =ROUNDUP(U26+X26, 0) | X26: 0.5 | Y26: 검측
F27: 슬라브철근 조립 | G27: ton | H27: =18.83*0.5 | I27: =인당생산성!H43 | J27: =ROUNDUP(H27/I27,0) | K27: =ROUNDUP(J27/T27,0) | M27: =작업조구성!$B$9 | N27: =CEILING(H28/($H$40*0.001)/200,1) | O27: =M27*N27 | P27: ='부분별 보정계수설정'!$B$8 | Q27: =ROUND(O27*P27/M27, 0)*M27 | T27: 1 | U27: =ROUNDUP(H27/(I27*Q27),0) | V27: =ROUNDUP(T27+X27, 0) | W27: =ROUNDUP(U27+X27, 0) | X27: 0.5 | Y27: 검측
F28: 타설 | G28: ㎥ | H28: 224 | I28: =인당생산성!H44 | J28: =K28*T28 | K28: =S28*6 | L28: 장비대수*4명 /일반층 | M28: 4 | N28: =S28 | O28: =N28*M28 | P28: 1 | Q28: =O28*P28 | R28: 콘크리트 펌프차 | S28: =CEILING(MIN(2, H28/'펌프카 부위별 타설량'!B7), 1) | T28: 1 | U28: =T28 | V28: =ROUNDUP(T28+X28, 0) | W28: =ROUNDUP(U28+X28, 0) | X28: 2 | Y28: 양생
B29: 옥탑층 | D29: =층고!C8 | F29: 먹매김 | G29: ㎡ | H29: 50 | I29: 250 | K29: 3 | M29: =작업조구성!$B$10 | N29: 1 | O29: =M29*N29 | P29: ='부분별 보정계수설정'!$B$10 | Q29: =ROUND(O29*P29/M29, 0)*M29 | T29: 1 | U29: =MAX(1, CEILING(H29/(N29*작업조구성!$D$10), 1)) | V29: =ROUNDUP(T29+X29, 0) | W29: =ROUNDUP(U29+X29, 0) | X29: 1 | Y29: 검측
F30: 벽 철근조립 | G30: ton | H30: =9.93/2 | I30: =인당생산성!H46 | J30: =ROUNDUP(H30/I30,0) | K30: =ROUNDUP(J30/T30,0) | M30: =작업조구성!$B$8 | N30: =CEILING(H32/(D29*0.001*25),1) | O30: =M30*N30 | P30: ='부분별 보정계수설정'!$B$9 | Q30: =ROUND(O30*P30/M30, 0)*M30 | T30: 1 | U30: =ROUNDUP(H30/(I30*Q30),0) | V30: =ROUNDUP(T30+X30, 0) | W30: =ROUNDUP(U30+X30, 0) | X30: 0.5 | Y30: 검측
F31: 벽 유로폼 설치 | G31: ㎡ | H31: 279.79 | I31: =인당생산성!H46 | J31: =ROUNDUP(H31/I31,0) | K31: =ROUNDUP(J31/T31,0) | M31: =작업조구성!$B$4 | O31: =M31*N31 | P31: ='부분별 보정계수설정'!$B$9 | Q31: =ROUND(O31*P31/M31, 0)*M31 | T31: 6 | U31: =ROUNDUP(H31/(I31*Q31),0) | V31: =ROUNDUP(T31+X31, 0) | W31: =ROUNDUP(U31+X31, 0) | X31: 0.5 | Y31: 검측
F32: 바닥 유로폼 설치 | G32: ㎡ | H32: 279.79 | I32: =인당생산성!H47 | J32: =ROUNDUP(H32/I32,0) | K32: =ROUNDUP(J32/T32,0) | M32: =작업조구성!$B$4 | O32: =M32*N32 | P32: ='부분별 보정계수설정'!$B$9 | Q32: =ROUND(O32*P32/M32, 0)*M32 | T32: 6 | U32: =ROUNDUP(H32/(I32*Q32),0) | V32: =ROUNDUP(T32+X32, 0) | W32: =ROUNDUP(U32+X32, 0) | X32: 0.5 | Y32: 검측
F33: 슬라브철근 조립 | G33: ton | H33: =9.93/2 | I33: =인당생산성!H48 | J33: =ROUNDUP(H33/I33,0) | K33: =ROUNDUP(J33/T33,0) | M33: =작업조구성!$B$9 | N33: =CEILING(H34/($H$40*0.001)/200,1) | O33: =M33*N33 | P33: ='부분별 보정계수설정'!$B$9 | Q33: =ROUND(O33*P33/M33, 0)*M33 | T33: 1 | U33: =ROUNDUP(H33/(I33*Q33),0) | V33: =ROUNDUP(T33+X33, 0) | W33: =ROUNDUP(U33+X33, 0) | X33: 0.5 | Y33: 검측
F34: 타설 | G34: ㎥ | H34: 102 | I34: =인당생산성!H49 | J34: =K34*T34 | K34: =S34*4 | L34: 장비대수*4명 /최상층 | M34: 4 | N34: =S34 | O34: =N34*M34 | P34: 1 | Q34: =O34*P34 | R34: 콘크리트 펌프차 | S34: =CEILING(MIN(2, H34/'펌프카 부위별 타설량'!B8), 1) | T34: 1 | U34: =T34 | V34: =ROUNDUP(T34+X34, 0) | W34: =ROUNDUP(U34+X34, 0) | X34: 2 | Y34: 양생
F35: 거푸집해체정리 | G35: ㎡ | H35: =(H32)*2 | I35: 50 | J35: =ROUNDUP(H35/I35,0) | K35: =ROUNDUP(J35/T35,0) | M35: =작업조구성!$B$5 | O35: =M35*N35 | P35: ='부분별 보정계수설정'!$B$4 | Q35: =ROUND(O35*P35/M35, 0)*M35 | T35: 1 | U35: =MAX(1, CEILING(H35/(N35*작업조구성!$D$10), 1)) | V35: =ROUNDUP(T35+X35, 0) | W35: =ROUNDUP(U35+X35, 0)
G37: 보보정계수 | H37: 1.2
G38: B2슬라브두께 | H38: 250
G39: B1슬라브두께 | H39: 250
G40: 지상층슬라브두께 | H40: 250

Sheet 주동지하 표준공정
K2: 참고자료 | O2: 작업면적기준 | Q2: 보정계수 적용 | U2: 참고자료 | W2: 참고자료
B3: 구분 | D3: 층수 | E3: 층고 | F3: 면적 | G3: 세부공종 | H3: 단위 | I3: 수량 | J3: 기준 인당 생산성 | K3: 총 투입인원 | L3: 1일 투입인원 | M3: 산정 기준 | N3: 작업조 기준인원 | O3: 최대 작업조 | P3: 최대 인원 | Q3: 보정계수 | R3: 보정최대작업가능인원 | S3: 투입장비명 | T3: 최대장비대수 | U3: 순작업일 | V3: 최소 순작업일 | W3: 총작업일수 | X3: 최소 총작업일 | Y3: 간접일 | Z3: 간접작업항목
B4: 버림 | G4: 버림틀 설치 | H4: ㎡ | I4: 40 | J4: =인당생산성!H2 | K4: =I4/J4 | L4: =ROUNDUP(K4/U4,0) | N4: =작업조구성!$B$6 | O4: =CEILING(I4/작업조구성!$D$11, 1) | P4: =N4*O4 | Q4: ='부분별 보정계수설정'!B2 | R4: =ROUND(P4*Q4/N4, 0)*N4 | U4: 1 | V4: =MAX(1, CEILING(I4/(O4*작업조구성!D11), 1)) | W4: =ROUNDUP(U4+Y4, 0) | X4: =ROUNDUP(V4+Y4, 0) | AB4: 보보정계수 | AC4: 1.2
G5: 버림 타설 | H5: ㎥ | I5: 228 | J5: =인당생산성!H3 | K5: =L5*U5 | L5: =T5*4 | M5: 장비대수*4명 /버림부분 | N5: 4 | O5: =T5 | P5: =O5*N5 | Q5: 1 | R5: =P5*Q5 | S5: 콘크리트 펌프차 | T5: =CEILING(MIN(2, I5/'펌프카 부위별 타설량'!B1), 1) | U5: 1 | V5: =U5 | W5: =ROUNDUP(U5+Y5, 0) | X5: =ROUNDUP(V5+Y5, 0) | Y5: 1 | Z5: 양생 | AB5: B2슬라브두께 | AC5: 250
B6: 기초 | G6: 먹메김 | H6: ㎡ | I6: 562 | J6: 250 | L6: 3 | N6: =작업조구성!$B$10 | O6: 1 | P6: =N6*O6 | Q6: ='부분별 보정계수설정'!$B$10 | R6: =ROUND(P6*Q6/N6, 0)*N6 | U6: 1 | V6: =MAX(1, CEILING(I6/(O6*작업조구성!$D$10), 1)) | W6: =ROUNDUP(U6+Y6, 0) | X6: =ROUNDUP(V6+Y6, 0) | AB6: B1슬라브두께 | AC6: 250
G7: 기초 철근조립 | H7: ton | I7: 110.62 | J7: =인당생산성!H5 | K7: =ROUNDUP(I7/J7,0) | L7: =ROUNDUP(K7/U7,0) | N7: =작업조구성!$B$7 | O7: =ROUNDUP(I6/작업조구성!$D$7,0) | P7: =N7*O7 | Q7: ='부분별 보정계수설정'!$B$3 | R7: =ROUND(P7*Q7/N7, 0)*N7 | U7: 6 | V7: =ROUNDUP(I7/(J7*R7),0) | W7: =ROUNDUP(U7+Y7, 0) | X7: =ROUNDUP(V7+Y7, 0) | Y7: 0.5 | Z7: 검측 | AB7: 지상층슬라브두께 | AC7: 250
G8: 끊어치기 작업 | H8: ㎡ | I8: 120 | J8: =인당생산성!H6 | K8: =ROUNDUP(I8/J8,0) | L8: =ROUNDUP(K8/U8,0) | N8: =작업조구성!$B$6 | O8: =CEILING(I8/작업조구성!$D$12, 1) | P8: =N8*O8 | Q8: ='부분별 보정계수설정'!B12 | R8: =ROUND(P8*Q8/N8, 0)*N8 | U8: 2 | V8: =ROUNDUP(I8/(J8*R8),0) | W8: =ROUNDUP(U8+Y8, 0) | X8: =ROUNDUP(V8+Y8, 0) | Y8: 0.5 | Z8: 검측
G9: 기초 타설 | H9: ㎥ | I9: 1643 | J9: =인당생산성!H7 | K9: =L9*U9 | L9: =T9*5 | M9: 장비대수*5명 /기초부분 | N9: 5 | O9: =T9 | P9: =O9*N9 | Q9: 1 | R9: =P9*Q9 | S9: 콘크리트 펌프차 | T9: =CEILING(MIN(2, I9/'펌프카 부위별 타설량'!B2), 1) | U9: 1 | V9: =U9 | W9: =ROUNDUP(U9+Y9, 0) | X9: =ROUNDUP(V9+Y9, 0) | Y9: 2 | Z9: 양생
B10: 지하층 | C10: 주동 지하 | D10: B2 | E10: =층고!C2 | G10: 먹매김 | H10: ㎡ | I10: 562 | J10: 250 | L10: 3 | N10: =작업조구성!$B$10 | O10: 1 | P10: =N10*O10 | Q10: ='부분별 보정계수설정'!$B$10 | R10: =ROUND(P10*Q10/N10, 0)*N10 | U10: 1 | V10: =MAX(1, CEILING(I10/(O10*작업조구성!$D$10), 1)) | W10: =ROUNDUP(U10+Y10, 0) | X10: =ROUNDUP(V10+Y10, 0)
G11: 벽 철근조립 | H11: ton | I11: =118.01*0.5 | J11: =인당생산성!H9 | K11: =ROUNDUP(I11/J11,0) | L11: =ROUNDUP(K11/U11,0) | N11: =작업조구성!$B$8 | O11: =CEILING(MAX(0, (I12+I13) - (I16/($AC$5/1000))*AC4) / ($E$10/1000) / 25,1) | P11: =N11*O11 | Q11: ='부분별 보정계수설정'!$B$4 | R11: =ROUND(P11*Q11/N11, 0)*N11 | U11: 5 | V11: =ROUNDUP(I11/(J11*R11),0) | W11: =ROUNDUP(U11+Y11, 0) | X11: =ROUNDUP(V11+Y11, 0) | Y11: 0.5 | Z11: 검측
G12: 벽 거푸집설치 | H12: ㎡ | I12: =4855*0.95/2 | J12: =인당생산성!H10 | K12: =ROUNDUP(I12/J12,0) | L12: =ROUNDUP(K12/U12,0) | N12: =작업조구성!$B$4 | P12: =N12*O12 | Q12: ='부분별 보정계수설정'!$B$4 | R12: =ROUND(P12*Q12/N12, 0)*N12 | U12: 17 | V12: =ROUNDUP(I12/(J12*R12),0)
G13: 바닥 거푸집설치 | H13: ㎡ | I13: =4855*0.95/2 | J13: =인당생산성!H10 | K13: =ROUNDUP(I13/J13,0) | L13: =ROUNDUP(K13/U13,0) | N13: =작업조구성!$B$4 | P13: =N13*O13 | Q13: ='부분별 보정계수설정'!$B$4 | R13: =ROUND(P13*Q13/N13, 0)*N13 | U13: 17 | V13: =ROUNDUP(I13/(J13*R13),0) | W13: =ROUNDUP(U13+Y13, 0) | X13: =ROUNDUP(V13+Y13, 0) | Y13: 1 | Z13: 보강/검측
G14: 슬라브철근 조립 | H14: ton | I14: =118.01*0.5 | J14: =인당생산성!H11 | K14: =ROUNDUP(I14/J14,0) | L14: =ROUNDUP(K14/U14,0) | N14: =작업조구성!$B$9 | O14: =CEILING(I16*0.5/($AC$5*0.001)/200,1) | P14: =N14*O14 | Q14: ='부분별 보정계수설정'!$B$4 | R14: =ROUND(P14*Q14/N14, 0)*N14 | U14: 5 | V14: =ROUNDUP(I14/(J14*R14),0) | W14: =ROUNDUP(U14+Y14, 0) | X14: =ROUNDUP(V14+Y14, 0) | Y14: 0.5 | Z14: 검측
G15: 마감작업 | I15: =4855*0.05 | J15: =인당생산성!H12 | K15: =ROUNDUP(I15/J15,0) | L15: =ROUNDUP(K15/U15,0) | N15: =작업조구성!$B$6 | O15: =CEILING(I15/작업조구성!$D$6, 1) | P15: =N15*O15 | Q15: ='부분별 보정계수설정'!B11 | R15: =ROUND(P15*Q15/N15, 0)*N15 | U15: 2 | V15: =ROUNDUP(I15/(J15*R15),0) | W15: =ROUNDUP(U15+Y15, 0) | X15: =ROUNDUP(V15+Y15, 0) | Y15: 0.5 | Z15: 검측
G16: 타설 | H16: ㎥ | I16: 782 | J16: =인당생산성!H13 | K16: =L16*U16 | L16: =T16*5 | M16: 장비대수*5명 /지하골조부분 | N16: 5 | O16: =T16 | P16: =O16*N16 | Q16: 1 | R16: =P16*Q16 | S16: 콘크리트 펌프차 | T16: =CEILING(MIN(2, I16/'펌프카 부위별 타설량'!B3), 1) | U16: 1 | V16: =U16 | W16: =ROUNDUP(U16+Y16, 0) | X16: =ROUNDUP(V16+Y16, 0) | Y16: 3 | Z16: 양생
G17: 거푸집해체정리 | I17: =(I13+I15+I12)*2 | J17: =인당생산성!H14 | K17: =ROUNDUP(I17/J17,0) | L17: =ROUNDUP(K17/U17,0) | N17: =작업조구성!$B$5 | P17: =N17*O17 | Q17: ='부분별 보정계수설정'!$B$4 | R17: =ROUND(P17*Q17/N17, 0)*N17 | U17: 16 | V17: =MAX(1, CEILING(I17/(O17*작업조구성!$D$10), 1)) | W17: =ROUNDUP(U17+Y17, 0) | X17: =ROUNDUP(V17+Y17, 0)
D18: B1 | E18: =층고!C3 | G18: 먹매김 | H18: ㎡ | I18: 562 | J18: 250 | L18: 3 | N18: =작업조구성!$B$10 | O18: 1 | P18: =N18*O18 | Q18: ='부분별 보정계수설정'!$B$10 | R18: =ROUND(P18*Q18/N18, 0)*N18 | U18: 1 | V18: =MAX(1, CEILING(I18/(O18*작업조구성!$D$10), 1)) | W18: =ROUNDUP(U18+Y18, 0) | X18: =ROUNDUP(V18+Y18, 0) | Y18: 1
G19: 벽 철근조립 | H19: ton | I19: =152.26*0.6*0.5 | J19: =인당생산성!H16 | K19: =ROUNDUP(I19/J19,0) | L19: =ROUNDUP(K19/U19,0) | N19: =작업조구성!$B$8 | O19: =CEILING(MAX(0, (I20+I21) - (I24/($AC$6/1000))*AC4) / ($E$18/1000) / 25,1) | P19: =N19*O19 | Q19: ='부분별 보정계수설정'!$B$4 | R19: =ROUND(P19*Q19/N19, 0)*N19 | U19: 5 | V19: =ROUNDUP(I19/(J19*R19),0) | W19: =ROUNDUP(U19+Y19, 0) | X19: =ROUNDUP(V19+Y19, 0) | Y19: 0.5 | Z19: 검측
G20: 벽 거푸집설치 | H20: ㎡ | I20: =5072*0.65/2 | J20: =인당생산성!H17 | K20: =ROUNDUP(I20/J20,0) | L20: =ROUNDUP(K20/U20,0) | N20: =작업조구성!$B$4 | P20: =N20*O20 | Q20: ='부분별 보정계수설정'!$B$4 | R20: =ROUND(P20*Q20/N20, 0)*N20 | U20: 19 | V20: =ROUNDUP(I20/(J20*R20),0) | W20: =ROUNDUP(U20+Y20, 0) | X20: =ROUNDUP(V20+Y20, 0) | Y20: 0.5 | Z20: 검측
G21: 바닥 거푸집설치 | H21: ㎡ | I21: =5072*0.65/2 | J21: =인당생산성!H17 | K21: =ROUNDUP(I21/J21,0) | L21: =ROUNDUP(K21/U21,0) | N21: =작업조구성!$B$4 | P21: =N21*O21 | Q21: ='부분별 보정계수설정'!$B$4 | R21: =ROUND(P21*Q21/N21, 0)*N21 | U21: 19 | V21: =ROUNDUP(I21/(J21*R21),0) | W21: =ROUNDUP(U21+Y21, 0) | X21: =ROUNDUP(V21+Y21, 0) | Y21: 0.5 | Z21: 검측
G22: 슬라브철근 조립 | H22: ton | I22: =152.26*0.6*0.5 | J22: =인당생산성!$H$18 | K22: =ROUNDUP(I22/J22,0) | L22: =ROUNDUP(K22/U22,0) | N22: =작업조구성!$B$9 | O22: =CEILING(I24*0.5/($AC$5*0.001)/200,1) | P22: =N22*O22 | Q22: ='부분별 보정계수설정'!$B$4 | R22: =ROUND(P22*Q22/N22, 0)*N22 | U22: 5 | V22: =ROUNDUP(I22/(J22*R22),0) | W22: =ROUNDUP(U22+Y22, 0) | X22: =ROUNDUP(V22+Y22, 0) | Y22: 0.5 | Z22: 검측
G23: 마감작업 | I23: =5072*0.05 | J23: =인당생산성!H19 | K23: =ROUNDUP(I23/J23,0) | L23: =ROUNDUP(K23/U23,0) | N23: =작업조구성!$B$6 | O23: =CEILING(I23/작업조구성!$D$6, 1) | P23: =N23*O23 | Q23: ='부분별 보정계수설정'!$B$4 | R23: =ROUND(P23*Q23/N23, 0)*N23 | U23: 2 | V23: =ROUNDUP(I23/(J23*R23),0) | W23: =ROUNDUP(U23+Y23, 0) | X23: =ROUNDUP(V23+Y23, 0) | Y23: 0.5 | Z23: 검측
G24: 타설 | H24: ㎥ | I24: =1247*0.6 | J24: =인당생산성!H13 | K24: =L24*U24 | L24: =T24*5 | M24: 장비대수*5명 /지하골조부분 | N24: 5 | O24: =T24 | P24: =O24*N24 | Q24: 1 | R24: =P24*Q24 | S24: 콘크리트 펌프차 | T24: =CEILING(MIN(2, I24/'펌프카 부위별 타설량'!B2), 1) | U24: 1 | V24: =U24 | W24: =ROUNDUP(U24+Y24, 0) | X24: =ROUNDUP(V24+Y24, 0) | Y24: 3 | Z24: 양생
G25: 벽 철근조립 | H25: ton | I25: =152.26*0.4*0.5 | J25: =인당생산성!H9 | K25: =ROUNDUP(I25/J25,0) | L25: =ROUNDUP(K25/U25,0) | N25: =작업조구성!$B$8 | O25: =CEILING(MAX(0, (I26) - (I28/($AC$6/1000))*AC4) / ($E$18/1000) / 25,1) | P25: =N25*O25 | Q25: ='부분별 보정계수설정'!$B$4 | R25: =ROUND(P25*Q25/N25, 0)*N25 | U25: 5 | V25: =ROUNDUP(I25/(J25*R25),0) | W25: =ROUNDUP(U25+Y25, 0) | X25: =ROUNDUP(V25+Y25, 0) | Y25: 0.5 | Z25: 검측
G26: 피트층 거푸집설치 | I26: =5072*0.3 | J26: =인당생산성!H17 | K26: =ROUNDUP(I26/J26,0) | L26: =ROUNDUP(K26/U26,0) | N26: =작업조구성!$B$6 | O26: =CEILING(I26/작업조구성!$D$6, 1) | P26: =N26*O26 | Q26: ='부분별 보정계수설정'!$B$4 | R26: =ROUND(P26*Q26/N26, 0)*N26 | U26: 2 | V26: =ROUNDUP(I26/(J26*R26),0) | W26: =ROUNDUP(U26+Y26, 0) | X26: =ROUNDUP(V26+Y26, 0) | Y26: 0.5 | Z26: 검측
G27: 슬라브 철근조립 | H27: ton | I27: =152.26*0.4*0.5 | J27: =인당생산성!H9 | K27: =ROUNDUP(I27/J27,0) | L27: =ROUNDUP(K27/U27,0) | N27: =작업조구성!$B$8 | O27: =CEILING(MAX(0, (I26+I28) - (#REF!/($AC$6/1000))*I37) / ($E$18/1000) / 25,1) | P27: =N27*O27 | Q27: ='부분별 보정계수설정'!$B$4 | R27: =ROUND(P27*Q27/N27, 0)*N27 | U27: 5 | V27: =ROUNDUP(I27/(J27*R27),0) | W27: =ROUNDUP(U27+Y27, 0) | X27: =ROUNDUP(V27+Y27, 0) | Y27: 0.5 | Z27: 검측
G28: 피트층 타설 | H28: ㎥ | I28: =1247*0.4 | J28: =인당생산성!H13 | K28: =L28*U28 | L28: =T28*5 | M28: 장비대수*5명 /지하골조부분 | N28: 5 | O28: =T28 | P28: =O28*N28 | Q28: 1 | R28: =P28*Q28 | S28: 콘크리트 펌프차 | T28: =CEILING(MIN(2, I28/'펌프카 부위별 타설량'!B4), 1) | U28: 1 | V28: =U28 | W28: =ROUNDUP(U28+Y28, 0) | X28: =ROUNDUP(V28+Y28, 0) | Y28: 3 | Z28: 양생
G29: 거푸집해체정리 | H29: ㎡ | I29: =(I21+I23+I20+I26)*2 | J29: =인당생산성!H21 | K29: =ROUNDUP(I29/J29,0) | L29: =ROUNDUP(K29/U29,0) | N29: =작업조구성!$B$5 | P29: =N29*O29 | Q29: ='부분별 보정계수설정'!$B$4 | R29: =ROUND(P29*Q29/N29, 0)*N29 | U29: 22 | V29: =MAX(1, CEILING(I29/(O29*작업조구성!$D$10), 1)) | W29: =ROUNDUP(U29+Y29, 0) | X29: =ROUNDUP(V29+Y29, 0)

Sheet 주차장  표준공정
K2: 참고자료 | O2: 작업면적기준 | Q2: 보정계수 적용 | U2: 참고자료 | W2: 참고자료
B3: 구분 | D3: 층수 | E3: 층고 | F3: 면적 | G3: 세부공종 | H3: 단위 | I3: 수량 | J3: 기준 인당 생산성 | K3: 총 투입인원 | L3: 1일 투입인원 | M3: 산정 기준 | N3: 작업조 기준인원 | O3: 최대 작업조 | P3: 최대 인원 | Q3: 보정계수 | R3: 보정최대작업가능인원 | S3: 투입장비명 | T3: 최대장비대수 | U3: 순작업일 | V3: 최소 순작업일 | W3: 총작업일수 | X3: 최소 총작업일 | Y3: 간접일 | Z3: 간접작업항목
B4: 버림 | G4: 버림틀 설치 | H4: ㎡ | I4: 0 | J4: =인당생산성!H2 | K4: =I4/J4 | L4: =ROUNDUP(K4/U4,0) | N4: =작업조구성!$B$6 | O4: =CEILING(I4/작업조구성!$D$11, 1) | P4: =N4*O4 | Q4: ='부분별 보정계수설정'!B2 | R4: =ROUND(P4*Q4/N4, 0)*N4 | U4: 1 | V4: =MAX(1, CEILING(I4/(O4*작업조구성!D11), 1)) | W4: =ROUNDUP(U4+Y4, 0) | X4: =ROUNDUP(V4+Y4, 0) | AB4: 보보정계수 | AC4: 1.2
G5: 버림 타설 | H5: ㎥ | I5: 228 | J5: =인당생산성!H3 | K5: =L5*U5 | L5: =T5*4 | M5: 장비대수*4명 /버림부분 | N5: 4 | O5: =T5 | P5: =O5*N5 | Q5: 1 | R5: =P5*Q5 | S5: 콘크리트 펌프차 | T5: =CEILING(MIN(2, I5/'펌프카 부위별 타설량'!B1), 1) | U5: 1 | V5: =U5 | W5: =ROUNDUP(U5+Y5, 0) | X5: =ROUNDUP(V5+Y5, 0) | Y5: 1 | Z5: 양생 | AB5: B2슬라브두께 | AC5: 250
B6: 기초 | G6: 먹메김 | H6: ㎡ | I6: 562 | J6: 250 | L6: 3 | N6: =작업조구성!$B$10 | O6: 1 | P6: =N6*O6 | Q6: ='부분별 보정계수설정'!$B$10 | R6: =ROUND(P6*Q6/N6, 0)*N6 | U6: 1 | V6: =MAX(1, CEILING(I6/(O6*작업조구성!$D$10), 1)) | W6: =ROUNDUP(U6+Y6, 0) | X6: =ROUNDUP(V6+Y6, 0) | AB6: B1슬라브두께 | AC6: 250
G7: 기초 철근조립 | H7: ton | I7: 110.62 | J7: =인당생산성!H5 | K7: =ROUNDUP(I7/J7,0) | L7: =ROUNDUP(K7/U7,0) | N7: =작업조구성!$B$7 | O7: =ROUNDUP(I6/작업조구성!$D$7,0) | P7: =N7*O7 | Q7: ='부분별 보정계수설정'!$B$3 | R7: =ROUND(P7*Q7/N7, 0)*N7 | U7: 6 | V7: =ROUNDUP(I7/(J7*R7),0) | W7: =ROUNDUP(U7+Y7, 0) | X7: =ROUNDUP(V7+Y7, 0) | Y7: 0.5 | Z7: 검측 | AB7: 지상층슬라브두께 | AC7: 250
G8: 끊어치기 작업 | H8: ㎡ | I8: 120 | J8: =인당생산성!H6 | K8: =ROUNDUP(I8/J8,0) | L8: =ROUNDUP(K8/U8,0) | N8: =작업조구성!$B$6 | O8: =CEILING(I8/작업조구성!$D$12, 1) | P8: =N8*O8 | Q8: ='부분별 보정계수설정'!B12 | R8: =ROUND(P8*Q8/N8, 0)*N8 | U8: 2 | V8: =ROUNDUP(I8/(J8*R8),0) | W8: =ROUNDUP(U8+Y8, 0) | X8: =ROUNDUP(V8+Y8, 0) | Y8: 0.5 | Z8: 검측
G9: 기초 타설 | H9: ㎥ | I9: 1643 | J9: =인당생산성!H7 | K9: =L9*U9 | L9: =T9*5 | M9: 장비대수*5명 /기초부분 | N9: 5 | O9: =T9 | P9: =O9*N9 | Q9: 1 | R9: =P9*Q9 | S9: 콘크리트 펌프차 | T9: =CEILING(MIN(2, I9/'펌프카 부위별 타설량'!B2), 1) | U9: 1 | V9: =U9 | W9: =ROUNDUP(U9+Y9, 0) | X9: =ROUNDUP(V9+Y9, 0) | Y9: 2 | Z9: 양생
B10: 지하층 | C10: 주차장 | D10: B2 | E10: =층고!C2 | G10: 먹매김 | H10: ㎡ | I10: 562 | J10: 250 | L10: 3 | N10: =작업조구성!$B$10 | O10: 1 | P10: =N10*O10 | Q10: ='부분별 보정계수설정'!$B$10 | R10: =ROUND(P10*Q10/N10, 0)*N10 | U10: 1 | V10: =MAX(1, CEILING(I10/(O10*작업조구성!$D$10), 1)) | W10: =ROUNDUP(U10+Y10, 0) | X10: =ROUNDUP(V10+Y10, 0)
G11: 벽 철근조립 | H11: ton | I11: =118.01*0.5 | J11: =인당생산성!H9 | K11: =ROUNDUP(I11/J11,0) | L11: =ROUNDUP(K11/U11,0) | N11: =작업조구성!$B$8 | O11: =CEILING(MAX(0, (I12+I13) - (I16/($AC$5/1000))*AC4) / ($E$10/1000) / 25,1) | P11: =N11*O11 | Q11: ='부분별 보정계수설정'!$B$4 | R11: =ROUND(P11*Q11/N11, 0)*N11 | U11: 5 | V11: =ROUNDUP(I11/(J11*R11),0) | W11: =ROUNDUP(U11+Y11, 0) | X11: =ROUNDUP(V11+Y11, 0) | Y11: 0.5 | Z11: 검측
G12: 벽 거푸집설치 | H12: ㎡ | I12: =4855*0.95/2 | J12: =인당생산성!H10 | K12: =ROUNDUP(I12/J12,0) | L12: =ROUNDUP(K12/U12,0) | N12: =작업조구성!$B$4 | P12: =N12*O12 | Q12: ='부분별 보정계수설정'!$B$4 | R12: =ROUND(P12*Q12/N12, 0)*N12 | U12: 17 | V12: =ROUNDUP(I12/(J12*R12),0)
G13: 바닥 거푸집설치 | H13: ㎡ | I13: =4855*0.95/2 | J13: =인당생산성!H10 | K13: =ROUNDUP(I13/J13,0) | L13: =ROUNDUP(K13/U13,0) | N13: =작업조구성!$B$4 | P13: =N13*O13 | Q13: ='부분별 보정계수설정'!$B$4 | R13: =ROUND(P13*Q13/N13, 0)*N13 | U13: 17 | V13: =ROUNDUP(I13/(J13*R13),0) | W13: =ROUNDUP(U13+Y13, 0) | X13: =ROUNDUP(V13+Y13, 0) | Y13: 1 | Z13: 보강/검측
G14: 슬라브철근 조립 | H14: ton | I14: =118.01*0.5 | J14: =인당생산성!H11 | K14: =ROUNDUP(I14/J14,0) | L14: =ROUNDUP(K14/U14,0) | N14: =작업조구성!$B$9 | O14: =CEILING(I16*0.5/($AC$5*0.001)/200,1) | P14: =N14*O14 | Q14: ='부분별 보정계수설정'!$B$4 | R14: =ROUND(P14*Q14/N14, 0)*N14 | U14: 5 | V14: =ROUNDUP(I14/(J14*R14),0) | W14: =ROUNDUP(U14+Y14, 0) | X14: =ROUNDUP(V14+Y14, 0) | Y14: 0.5 | Z14: 검측
G15: 마감작업 | I15: =4855*0.05 | J15: =인당생산성!H12 | K15: =ROUNDUP(I15/J15,0) | L15: =ROUNDUP(K15/U15,0) | N15: =작업조구성!$B$6 | O15: =CEILING(I15/작업조구성!$D$6, 1) | P15: =N15*O15 | Q15: ='부분별 보정계수설정'!B11 | R15: =ROUND(P15*Q15/N15, 0)*N15 | U15: 2 | V15: =ROUNDUP(I15/(J15*R15),0) | W15: =ROUNDUP(U15+Y15, 0) | X15: =ROUNDUP(V15+Y15, 0) | Y15: 0.5 | Z15: 검측
G16: 타설 | H16: ㎥ | I16: 782 | J16: =인당생산성!H13 | K16: =L16*U16 | L16: =T16*5 | M16: 장비대수*5명 /지하골조부분 | N16: 5 | O16: =T16 | P16: =O16*N16 | Q16: 1 | R16: =P16*Q16 | S16: 콘크리트 펌프차 | T16: =CEILING(MIN(2, I16/'펌프카 부위별 타설량'!B3), 1) | U16: 1 | V16: =U16 | W16: =ROUNDUP(U16+Y16, 0) | X16: =ROUNDUP(V16+Y16, 0) | Y16: 3 | Z16: 양생
G17: 거푸집해체정리 | I17: =(I13+I15+I12)*2 | J17: =인당생산성!H14 | K17: =ROUNDUP(I17/J17,0) | L17: =ROUNDUP(K17/U17,0) | N17: =작업조구성!$B$5 | P17: =N17*O17 | Q17: ='부분별 보정계수설정'!$B$4 | R17: =ROUND(P17*Q17/N17, 0)*N17 | U17: 16 | V17: =MAX(1, CEILING(I17/(O17*작업조구성!$D$10), 1)) | W17: =ROUNDUP(U17+Y17, 0) | X17: =ROUNDUP(V17+Y17, 0)
D18: B1 | E18: =층고!C3 | G18: 먹매김 | H18: ㎡ | I18: 562 | J18: 250 | L18: 3 | N18: =작업조구성!$B$10 | O18: 1 | P18: =N18*O18 | Q18: ='부분별 보정계수설정'!$B$10 | R18: =ROUND(P18*Q18/N18, 0)*N18 | U18: 1 | V18: =MAX(1, CEILING(I18/(O18*작업조구성!$D$10), 1)) | W18: =ROUNDUP(U18+Y18, 0) | X18: =ROUNDUP(V18+Y18, 0) | Y18: 1
G19: 벽 철근조립 | H19: ton | I19: =152.26*0.6*0.5 | J19: =인당생산성!H16 | K19: =ROUNDUP(I19/J19,0) | L19: =ROUNDUP(K19/U19,0) | N19: =작업조구성!$B$8 | O19: =CEILING(MAX(0, (I20+I21) - (I24/($AC$6/1000))*AC4) / ($E$18/1000) / 25,1) | P19: =N19*O19 | Q19: ='부분별 보정계수설정'!$B$4 | R19: =ROUND(P19*Q19/N19, 0)*N19 | U19: 5 | V19: =ROUNDUP(I19/(J19*R19),0) | W19: =ROUNDUP(U19+Y19, 0) | X19: =ROUNDUP(V19+Y19, 0) | Y19: 0.5 | Z19: 검측
G20: 벽 거푸집설치 | H20: ㎡ | I20: =5072*0.65/2 | J20: =인당생산성!H17 | K20: =ROUNDUP(I20/J20,0) | L20: =ROUNDUP(K20/U20,0) | N20: =작업조구성!$B$4 | P20: =N20*O20 | Q20: ='부분별 보정계수설정'!$B$4 | R20: =ROUND(P20*Q20/N20, 0)*N20 | U20: 19 | V20: =ROUNDUP(I20/(J20*R20),0) | W20: =ROUNDUP(U20+Y20, 0) | X20: =ROUNDUP(V20+Y20, 0) | Y20: 0.5 | Z20: 검측
G21: 바닥 거푸집설치 | H21: ㎡ | I21: =5072*0.65/2 | J21: =인당생산성!H17 | K21: =ROUNDUP(I21/J21,0) | L21: =ROUNDUP(K21/U21,0) | N21: =작업조구성!$B$4 | P21: =N21*O21 | Q21: ='부분별 보정계수설정'!$B$4 | R21: =ROUND(P21*Q21/N21, 0)*N21 | U21: 19 | V21: =ROUNDUP(I21/(J21*R21),0) | W21: =ROUNDUP(U21+Y21, 0) | X21: =ROUNDUP(V21+Y21, 0) | Y21: 0.5 | Z21: 검측
G22: 슬라브철근 조립 | H22: ton | I22: =152.26*0.6*0.5 | J22: =인당생산성!$H$18 | K22: =ROUNDUP(I22/J22,0) | L22: =ROUNDUP(K22/U22,0) | N22: =작업조구성!$B$9 | O22: =CEILING(I24*0.5/($AC$5*0.001)/200,1) | P22: =N22*O22 | Q22: ='부분별 보정계수설정'!$B$4 | R22: =ROUND(P22*Q22/N22, 0)*N22 | U22: 5 | V22: =ROUNDUP(I22/(J22*R22),0) | W22: =ROUNDUP(U22+Y22, 0) | X22: =ROUNDUP(V22+Y22, 0) | Y22: 0.5 | Z22: 검측
G23: 마감작업 | I23: =5072*0.05 | J23: =인당생산성!H19 | K23: =ROUNDUP(I23/J23,0) | L23: =ROUNDUP(K23/U23,0) | N23: =작업조구성!$B$6 | O23: =CEILING(I23/작업조구성!$D$6, 1) | P23: =N23*O23 | Q23: ='부분별 보정계수설정'!$B$4 | R23: =ROUND(P23*Q23/N23, 0)*N23 | U23: 2 | V23: =ROUNDUP(I23/(J23*R23),0) | W23: =ROUNDUP(U23+Y23, 0) | X23: =ROUNDUP(V23+Y23, 0) | Y23: 0.5 | Z23: 검측
G24: 타설 | H24: ㎥ | I24: =1247*0.6 | J24: =인당생산성!H13 | K24: =L24*U24 | L24: =T24*5 | M24: 장비대수*5명 /지하골조부분 | N24: 5 | O24: =T24 | P24: =O24*N24 | Q24: 1 | R24: =P24*Q24 | S24: 콘크리트 펌프차 | T24: =CEILING(MIN(2, I24/'펌프카 부위별 타설량'!B2), 1) | U24: 1 | V24: =U24 | W24: =ROUNDUP(U24+Y24, 0) | X24: =ROUNDUP(V24+Y24, 0) | Y24: 3 | Z24: 양생
G25: 거푸집해체정리 | H25: ㎡ | I25: =(I21+I23+I20)*2 | J25: =인당생산성!H21 | K25: =ROUNDUP(I25/J25,0) | L25: =ROUNDUP(K25/U25,0) | N25: =작업조구성!$B$5 | P25: =N25*O25 | Q25: ='부분별 보정계수설정'!$B$4 | R25: =ROUND(P25*Q25/N25, 0)*N25 | U25: 22 | V25: =MAX(1, CEILING(I25/(O25*작업조구성!$D$10), 1)) | W25: =ROUNDUP(U25+Y25, 0) | X25: =ROUNDUP(V25+Y25, 0)

Sheet 층고6.5m이상구간
K2: 참고자료 | O2: 작업면적기준 | Q2: 보정계수 적용 | U2: 참고자료 | W2: 참고자료
B3: 구분 | D3: 층수 | E3: 층고 | F3: 면적 | G3: 세부공종 | H3: 단위 | I3: 수량 | J3: 기준 인당 생산성 | K3: 총 투입인원 | L3: 1일 투입인원 | M3: 산정 기준 | N3: 작업조 기준인원 | O3: 최대 작업조 | P3: 최대 인원 | Q3: 보정계수 | R3: 보정최대작업가능인원 | S3: 투입장비명 | T3: 최대장비대수 | U3: 순작업일 | V3: 최소 순작업일 | W3: 총작업일수 | X3: 최소 총작업일 | Y3: 간접일 | Z3: 간접작업항목
B4: 버림 | G4: 버림틀 설치 | H4: ㎡ | I4: 0 | J4: =인당생산성!H2 | K4: =I4/J4 | L4: =ROUNDUP(K4/U4,0) | N4: =작업조구성!$B$6 | O4: =CEILING(I4/작업조구성!$D$11, 1) | P4: =N4*O4 | Q4: ='부분별 보정계수설정'!B2 | R4: =ROUND(P4*Q4/N4, 0)*N4 | U4: 1 | V4: =MAX(1, CEILING(I4/(O4*작업조구성!D11), 1)) | W4: =ROUNDUP(U4+Y4, 0) | X4: =ROUNDUP(V4+Y4, 0) | AB4: 보보정계수 | AC4: 1.2
G5: 버림 타설 | H5: ㎥ | I5: 228 | J5: =인당생산성!H3 | K5: =L5*U5 | L5: =T5*4 | M5: 장비대수*4명 /버림부분 | N5: 4 | O5: =T5 | P5: =O5*N5 | Q5: 1 | R5: =P5*Q5 | S5: 콘크리트 펌프차 | T5: =CEILING(MIN(2, I5/'펌프카 부위별 타설량'!B1), 1) | U5: 1 | V5: =U5 | W5: =ROUNDUP(U5+Y5, 0) | X5: =ROUNDUP(V5+Y5, 0) | Y5: 1 | Z5: 양생 | AB5: B2슬라브두께 | AC5: 250
B6: 기초 | G6: 먹메김 | H6: ㎡ | I6: 562 | J6: 250 | L6: 3 | N6: =작업조구성!$B$10 | O6: 1 | P6: =N6*O6 | Q6: ='부분별 보정계수설정'!$B$10 | R6: =ROUND(P6*Q6/N6, 0)*N6 | U6: 1 | V6: =MAX(1, CEILING(I6/(O6*작업조구성!$D$10), 1)) | W6: =ROUNDUP(U6+Y6, 0) | X6: =ROUNDUP(V6+Y6, 0) | AB6: B1슬라브두께 | AC6: 250
G7: 기초 철근조립 | H7: ton | I7: 110.62 | J7: =인당생산성!H5 | K7: =ROUNDUP(I7/J7,0) | L7: =ROUNDUP(K7/U7,0) | N7: =작업조구성!$B$7 | O7: =ROUNDUP(I6/작업조구성!$D$7,0) | P7: =N7*O7 | Q7: ='부분별 보정계수설정'!$B$3 | R7: =ROUND(P7*Q7/N7, 0)*N7 | U7: 6 | V7: =ROUNDUP(I7/(J7*R7),0) | W7: =ROUNDUP(U7+Y7, 0) | X7: =ROUNDUP(V7+Y7, 0) | Y7: 0.5 | Z7: 검측 | AB7: 지상층슬라브두께 | AC7: 250
G8: 끊어치기 작업 | H8: ㎡ | I8: 120 | J8: =인당생산성!H6 | K8: =ROUNDUP(I8/J8,0) | L8: =ROUNDUP(K8/U8,0) | N8: =작업조구성!$B$6 | O8: =CEILING(I8/작업조구성!$D$12, 1) | P8: =N8*O8 | Q8: ='부분별 보정계수설정'!B12 | R8: =ROUND(P8*Q8/N8, 0)*N8 | U8: 2 | V8: =ROUNDUP(I8/(J8*R8),0) | W8: =ROUNDUP(U8+Y8, 0) | X8: =ROUNDUP(V8+Y8, 0) | Y8: 0.5 | Z8: 검측
G9: 기초 타설 | H9: ㎥ | I9: 1643 | J9: =인당생산성!H7 | K9: =L9*U9 | L9: =T9*5 | M9: 장비대수*5명 /기초부분 | N9: 5 | O9: =T9 | P9: =O9*N9 | Q9: 1 | R9: =P9*Q9 | S9: 콘크리트 펌프차 | T9: =CEILING(MIN(2, I9/'펌프카 부위별 타설량'!B2), 1) | U9: 1 | V9: =U9 | W9: =ROUNDUP(U9+Y9, 0) | X9: =ROUNDUP(V9+Y9, 0) | Y9: 2 | Z9: 양생
B10: 지하층 | C10: 층고6.5m이상구간 | E10: 6500 | G10: 먹매김 | H10: ㎡ | I10: 562 | J10: 250 | L10: 3 | N10: =작업조구성!$B$10 | O10: 1 | P10: =N10*O10 | Q10: ='부분별 보정계수설정'!$B$10 | R10: =ROUND(P10*Q10/N10, 0)*N10 | U10: 1 | V10: =MAX(1, CEILING(I10/(O10*작업조구성!$D$10), 1)) | W10: =ROUNDUP(U10+Y10, 0) | X10: =ROUNDUP(V10+Y10, 0)
G11: 벽 철근조립 | H11: ton | I11: =118.01*0.5 | J11: =인당생산성!H9 | K11: =ROUNDUP(I11/J11,0) | L11: =ROUNDUP(K11/U11,0) | N11: =작업조구성!$B$8 | O11: =CEILING(MAX(0, (I13+I14) - (I17/($AC$5/1000))*AC4) / ($E$10/1000) / 25,1) | P11: =N11*O11 | Q11: ='부분별 보정계수설정'!$B$4 | R11: =ROUND(P11*Q11/N11, 0)*N11 | U11: 5 | V11: =ROUNDUP(I11/(J11*R11),0) | W11: =ROUNDUP(U11+Y11, 0) | X11: =ROUNDUP(V11+Y11, 0) | Y11: 0.5 | Z11: 검측
G12: 시스템동바리 | H12: ㎡ | I12: 400 | J12: 20 | K12: =ROUNDUP(I12/J12,0) | L12: =ROUNDUP(K12/U12,0) | N12: 5 | O12: =MAX(1, CEILING( (I12*(E10*0.001)) / (J12*N12) / U12, 1)) | P12: =N12*O12 | Q12: ='부분별 보정계수설정'!$B$4 | R12: =ROUND(P12*Q12/N12, 0)*N12 | U12: 6 | V12: =ROUNDUP(I12/(J12*R12),0)
G13: 벽 거푸집설치 | H13: ㎡ | I13: =4855*0.95/2 | J13: =인당생산성!H10 | K13: =ROUNDUP(I13/J13,0) | L13: =ROUNDUP(K13/U13,0) | N13: =작업조구성!$B$4 | P13: =N13*O13 | Q13: ='부분별 보정계수설정'!$B$4 | R13: =ROUND(P13*Q13/N13, 0)*N13 | U13: 17 | V13: =ROUNDUP(I13/(J13*R13),0)
G14: 바닥 거푸집설치 | H14: ㎡ | I14: =4855*0.95/2 | J14: =인당생산성!H10 | K14: =ROUNDUP(I14/J14,0) | L14: =ROUNDUP(K14/U14,0) | N14: =작업조구성!$B$4 | P14: =N14*O14 | Q14: ='부분별 보정계수설정'!$B$4 | R14: =ROUND(P14*Q14/N14, 0)*N14 | U14: 17 | V14: =ROUNDUP(I14/(J14*R14),0) | W14: =ROUNDUP(U14+Y14, 0) | X14: =ROUNDUP(V14+Y14, 0) | Y14: 1 | Z14: 보강/검측
G15: 슬라브철근 조립 | H15: ton | I15: =118.01*0.5 | J15: =인당생산성!H11 | K15: =ROUNDUP(I15/J15,0) | L15: =ROUNDUP(K15/U15,0) | N15: =작업조구성!$B$9 | O15: =CEILING(I17*0.5/($AC$5*0.001)/200,1) | P15: =N15*O15 | Q15: ='부분별 보정계수설정'!$B$4 | R15: =ROUND(P15*Q15/N15, 0)*N15 | U15: 5 | V15: =ROUNDUP(I15/(J15*R15),0) | W15: =ROUNDUP(U15+Y15, 0) | X15: =ROUNDUP(V15+Y15, 0) | Y15: 0.5 | Z15: 검측
G16: 마감작업 | I16: =4855*0.05 | J16: =인당생산성!H12 | K16: =ROUNDUP(I16/J16,0) | L16: =ROUNDUP(K16/U16,0) | N16: =작업조구성!$B$6 | O16: =CEILING(I16/작업조구성!$D$6, 1) | P16: =N16*O16 | Q16: ='부분별 보정계수설정'!B11 | R16: =ROUND(P16*Q16/N16, 0)*N16 | U16: 2 | V16: =ROUNDUP(I16/(J16*R16),0) | W16: =ROUNDUP(U16+Y16, 0) | X16: =ROUNDUP(V16+Y16, 0) | Y16: 0.5 | Z16: 검측
G17: 타설 | H17: ㎥ | I17: 782 | J17: =인당생산성!H13 | K17: =L17*U17 | L17: =T17*5 | M17: 장비대수*5명 /지하골조부분 | N17: 5 | O17: =T17 | P17: =O17*N17 | Q17: 1 | R17: =P17*Q17 | S17: 콘크리트 펌프차 | T17: =CEILING(MIN(2, I17/'펌프카 부위별 타설량'!B3), 1) | U17: 1 | V17: =U17 | W17: =ROUNDUP(U17+Y17, 0) | X17: =ROUNDUP(V17+Y17, 0) | Y17: 3 | Z17: 양생
G18: 거푸집해체정리 | I18: =(I14+I16+I13)*2 | J18: =인당생산성!H14 | K18: =ROUNDUP(I18/J18,0) | L18: =ROUNDUP(K18/U18,0) | N18: =작업조구성!$B$5 | P18: =N18*O18 | Q18: ='부분별 보정계수설정'!$B$4 | R18: =ROUND(P18*Q18/N18, 0)*N18 | U18: 16 | V18: =MAX(1, CEILING(I18/(O18*작업조구성!$D$10), 1)) | W18: =ROUNDUP(U18+Y18, 0) | X18: =ROUNDUP(V18+Y18, 0)

Sheet 층고
A1: 구분 | B1: 층수
A2: 지하 | B2: B2 | C2: 3500
A3: 지하 | B3: B1 | C3: 5400
A4: 일반층 | C4: 3050
A5: 셋팀층 | C5: 2850
A6: 기준층 | C6: 2850
A7: 최상층 | C7: 3050
A8: 옥탑층 | B8: 옥탑1 | C8: 2650
B9: 옥탑2 | C9: 2650

Sheet 작업조구성
A1: 구 분 | B1: 작업조원 | C1: 표준 | D1: 구획산정 보정기준 | E1: 권장 작업조 산정 기준
A2: 갱폼 | B2: 4 | E2: 동시에 작업 할 수 있는 작업면의 수
A3: 알폼 | B3: 3 | E3: 동시에 작업 할 수 있는 작업면의 수
A4: 유로폼 | B4: 2 | E4: 동시에 작업 할 수 있는 작업면의 수
A5: 해체/정리 | B5: 2 | C5: 250 | D5: 250 | E5: 250㎡/작업면적
A6: 마감/보강 | B6: 2 | C6: 40 | D6: 40 | E6: 40㎡/작업면적
A7: 기초 철근 | B7: 4 | C7: 200 | D7: 200 | E7: 200㎡/기초작업면적
A8: 벽 철근 | B8: 3 | C8: 25 | D8: 25 | E8: 벽체라인 25ｍ/작업면
A9: 슬라브 철근 | B9: 3 | C9: 200 | D9: 200 | E9: 200㎡/작업면적
A10: 먹매김 | B10: 2 | C10: 500 | D10: 500 | E10: 동시에 먹메김 할 수 있는 작업면(구획)의 수 (권장 환산: 500㎡/구획 또는 벽체라인 50m/구획 중 큰 값 적용)
A11: 버림틀설치 | B11: 2 | C11: 20 | D11: 20
A12: 끊어치기 | B12: 2 | C12: 20 | D12: 20

Sheet 공종별 인원 상,하한 설정
A1: 공종 | C1: 하한 | D1: 기본값 | E1: 권장 | F1: 공기지연
A2: 갱폼 | C2: 12 | D2: 16 | E2: 20 | F2: 24
A3: 알폼 | C3: 12 | D3: 15 | E3: 18 | F3: 21
A4: 유로폼 | B4: 옥탑 | C4: 6 | D4: 8 | E4: 8 | F4: 8
A5: 유로폼 | B5: 지상 필로티,부대시설 | C5: 6 | D5: 8 | E5: 10 | F5: 12
A6: 유로폼 | B6: 지하슬라브 | C6: 6 | D6: 8 | E6: 10 | F6: 12
A7: 유로폼 | B7: 지하 벽 | C7: 8 | D7: 12 | E7: 16 | F7: 20
A8: 철근 | B8: 슬라브 | C8: 12 | D8: 15 | E8: 18 | F8: 21
A9: 철근 | B9: 지상벽 | C9: 9 | D9: 12 | E9: 15 | F9: 18
A10: 철근 | B10: 지하벽 | C10: 12 | D10: 15 | E10: 18 | F10: 21
A11: 철근 | B11: 기초 | C11: 16 | D11: 20 | E11: 24 | F11: 27
A12: 해체/정리 | C12: 10 | D12: 14 | E12: 16 | F12: 20
A13: 마감/보강 | C13: 6 | D13: 8 | E13: 10 | F13: 12

Sheet 부분별 보정계수설정
A1: 구 분 | B1: 보정계수
A2: 버림 | B2: 1
A3: 기초 | B3: 1.3
A4: 지하 | B4: 1.2
A5: 일반층 | B5: 0.85
A6: 셋팅층 | B6: 0.9
A7: 기준층 | B7: 1
A8: 최상층 | B8: 0.85
A9: PH층 | B9: 0.7
A10: 먹매김 | B10: 1
A11: 마감/보강 | B11: 1
A12: 끊어치기 | B12: 1

Sheet 거푸집 계열 작업면, 작업면적 추정 산식
A1: 공종·부위 | B1: 물량표 입력 | C1: 추정 파라미터 | D1: 작업면/작업면적 산정식(예시) | E1: Front/Zone 산정 | F1: 비고(오차/보정 포인트)
A2: 갱폼(지상 벽체) | B2: 갱폼㎡ | C2: h | D2: 벽체연장 L_g = 갱폼㎡ / h | E2: Front_g = CEILING(L_g / L_front) | F2: 갱폼㎡가 “벽체면적”이라 가장 깔끔. 코어/외곽 분리 없으면 Front는 과대/과소 가능 → cap 상·하한으로 clamp 권장
A3: 알폼(지상 벽체) | B3: 알폼㎡ | C3: h | D3: 벽체연장 L_a = 알폼㎡ / h | E3: Front_a = CEILING(L_a / L_front) | F3: 알폼은 구획을 잘게 나눌 수 있어 Front 추정이 현실적. 단, 코어 집중형 평면은 Front가 과대될 수 있음
A4: 옥탑 | B4: 형틀㎡(또는 유로폼으로 간주) | C4: h_PH, k_beam_PH | D4: ① 슬라브면적 A_s = 콘크리트㎥ / t_slab (가능하면 PH 두께 별도) ② 슬라브거푸집 A_sf = A_s × k_beam_PH ③ 벽체유로폼㎡ = MAX(0, 형틀㎡ − A_sf) | E4: Front_PH = CEILING((벽체유로폼㎡/h_PH)/L_front), Zone_slab = CEILING(A_s / A_zone_slab) | F4: 옥탑은 보정이 큰 구간. PH는 “상한(권장)=상한(하드)”로 묶는 게 안정적(사람 더 넣어도 안 빨라짐)
A5: 유로폼(지상 필로티·부대시설 – 벽체) | B5: 형틀㎡ | C5: h_pil, t_slab_pil, | D5: ① A_s = 콘크리트㎥ / t_slab_pil ② A_sf = A_s × k_beam_pil ③ 벽체유로폼㎡ = MAX(0, 형틀㎡ − A_sf) ④ 벽체연장 L = 벽체유로폼㎡ / h_pil | E5: Front = CEILING(L / L_front) | F5: 필로티는 기둥/보/단차가 많아 k_beam을 높게(1.2~1.3) 잡아야 “벽체유로폼” 과대추정이 줄어듦
B6: (갱폼/알폼이 0 또는 매우 적은 층) | C6: k_beam_pil
A7: 유로폼(지하 슬라브 – 저면/보·턱) | B7: 형틀㎡, 콘크리트㎥ | C7: t_slab_ug, k_beam_ug | D7: ① 슬라브면적 A_s = 콘크리트㎥ / t_slab_ug ② 슬라브거푸집 A_sf = A_s × k_beam_ug | E7: Zone_slab = CEILING(A_s / A_zone_slab) | F7: 지하 슬라브는 벽체와 분리 필요. 형틀㎡ 중 슬라브 몫을 먼저 빼고 남는 걸 벽체로(아래 지하벽 계산)
A8: 유로폼(지하 벽체 – 외곽/내력벽) | B8: 형틀㎡, 콘크리트㎥ | C8: h_ug, t_slab_ug, k_beam_ug | D8: ① A_s = 콘크리트㎥ / t_slab_ug ② A_sf = A_s × k_beam_ug ③ 벽체유로폼㎡ = MAX(0, 형틀㎡ − A_sf) ④ 벽체연장 L = 벽체유로폼㎡ / h_ug | E8: Front = CEILING(L / L_front) | F8: 지하벽은 cap이 “전선” 지배. h_ug를 잘못 주면 Front가 크게 흔들림 → 지하층고만큼은 입력 추천

Sheet 철근 작업면,작업면적(Zone,Front) 추정 산식
A1: 철근 부위 | B1: 물량표 입력 | C1: 추정 파라미터 | D1: 작업면/작업면적 산정식(예시) | E1: Zone/Front 산정 | F1: 비고(오차/보정 포인트)
A2: 슬라브 철근(지상/지하 공통) | B2: 콘크리트㎥(우선), 철근ton(검증) | C2: t_slab, A_zone_slab=200㎡ | D2: 슬라브면적 A_s = 콘크리트㎥ / t_slab | E2: Zone_slab = CEILING(A_s / 200) | F2: 슬라브는 면적 구획이 cap을 결정. 철근ton은 “난이도 검증”용(ton/㎡가 높으면 생산성 보정)
A3: 지상 벽체 철근(갱폼/알폼 기반) | B3: 갱폼㎡+알폼㎡ | C3: h | D3: 벽체연장 L = (갱폼㎡+알폼㎡)/h | E3: Front = CEILING(L / 25m) | F3: 지상 벽체철근은 폼(벽체면적)과 강하게 연동됨. 벽체 면적이 곧 작업면
A4: 지하 벽체 철근(유로폼 기반) | B4: 형틀㎡(+ 콘크리트㎥로 슬라브 제거) | C4: h_ug, t_slab_ug, k_beam_ug | D4: ① A_s = 콘크리트㎥ / t_slab_ug ② A_sf=A_s×k_beam_ug ③ 벽체유로폼㎡=MAX(0, 형틀㎡−A_sf) ④ L=벽체유로폼㎡/h_ug | E4: Front=CEILING(L/25m) | F4: 지하벽 철근은 전선 기반이 가장 맞음. 지하층고 입력이 중요
A5: 기초 철근(매트/독립기초) | B5: 콘크리트㎥(기초), 철근ton | C5: t_mat(기초두께), A_zone_slab=200㎡ | D5: 기초면적 A_f = 기초콘크리트㎥ / t_mat | E5: Zone_found = CEILING(A_f / 200) | F5: 기초는 “자유구획”이라 Zone 기반이 맞음. 두께(t_mat)만 알면 면적이 안정적으로 나옴

Sheet 인당생산성
B1: 구분 | C1: 층수 | D1: 층고 | E1: 면적 | F1: 세부공종 | G1: 단 위 | H1: 인당 생산성
B2: 버림 | F2: 버림틀 설치 | G2: ㎡ | H2: 30
F3: 버림 타설 | G3: ㎥ | H3: 130
B4: 기초 | F4: 먹메김
F5: 기초 철근조립 | G5: ton | H5: 1.1
F6: 끊어치기 작업 | G6: ㎡ | H6: 10
F7: 기초 타설 | G7: ㎥ | H7: 130
B8: 지하층 | C8: B2 | D8: =층고!C2 | F8: 먹매김
F9: 벽 철근조립 | G9: ton | H9: 0.8
F10: 벽 거푸집설치 | G10: ㎡ | H10: 11
F11: 바닥 거푸집설치 | G11: ton | H11: 0.8
F12: 슬라브철근 조립 | G12: ㎡ | H12: 11
F13: 마감작업 | G13: ㎥ | H13: 130
F14: B2 타설 | H14: 50
F15: 거푸집해체정리
C16: B1 | D16: =층고!C3 | F16: 먹매김 | G16: ton | H16: 0.7
F17: 벽 철근조립 | G17: ㎡ | H17: 9
F18: 벽 거푸집설치 | G18: ton | H18: 0.7
F19: 바닥 거푸집설치 | G19: ㎡ | H19: 11
F20: 슬라브철근 조립 | G20: ㎥ | H20: 130
F21: 마감작업 | G21: ㎡ | H21: 50
F22: B1 타설
F23: 벽 철근조립 | G23: ton | H23: 0.7
F24: 피트층 거푸집설치 | G24: ㎡ | H24: 9
F25: 슬라브 철근조립 | G25: ton | H25: 0.6
F26: 피트층 타설 | G26: ㎥ | H26: 130
F27: 거푸집해체정리
B28: 일반층 | D28: =층고!C2 | F28: 먹매김 | G28: ㎡ | H28: 30
F29: 벽 철근조립 | G29: ton | H29: 0.8
F30: 벽 유로폼 설치 | G30: ㎡ | H30: 30
F31: 바닥 유로폼 설치 | G31: ton | H31: 0.9
F32: 슬라브철근 조립 | G32: ㎥ | H32: 130
F33: 타설
F34: 거푸집해체정리 | G34: ㎡ | H34: 60
B35: 셋팅층 | D35: =층고!C3 | F35: 먹매김 | G35: ton | H35: 0.8
F36: 갱폼설치 | G36: ㎡ | H36: 60
F37: 벽 철근조립 | G37: ton | H37: 0.9
F38: 알폼조립 | G38: ㎥ | H38: 130
F39: 슬라브철근 조립
F40: 타설 | G40: ㎡ | H40: 60
...

Sheet 펌프카 부위별 타설량
A1: 버림 | B1: 650
A2: 기초 대당타설량 | B2: 650
A3: 지하층 대당타설량 | B3: 500
A4: 일반층 대당타설량 | B4: 200
A5: 셋팀층 대당타설량 | B5: 400
A6: 기준층 대당타설량 | B6: 320
A7: 최상층 대당타설량 | B7: 230
A8: PH층 대당타설량 | B8: 230
A10: 펌프차 대수산정기준 : 동별 최대 2대
